Workbook

Sheet Read me
B2: IFRS 17 FINANCIAL STATEMENTS
B3: A step-by-step model of IFRS 17 accounting mechanics
B5: ABOUT THIS FILE
B6: This workbook is a teaching model that illustrates IFRS 17 (Insurance Contracts) through a progressive series of examples. It follows a single hypothetical insurance contract — a 3-year coverage period policy with 1,000 in upfront premiums — across four increasingly realistic scenarios. Each version builds a complete set of financial statements (Income Statement, Balance Sheet, and Cash Flow Reconciliation) so you can trace exactly how each new concept changes the numbers. The model decomposes the insurance liability into its IFRS 17 building blocks: Best Estimate Liability (BEL), Risk Adjustment (RA), and Contractual Service Margin (CSM), and shows how each block rolls forward period by period.
B8: MODEL STRUCTURE
B9: The workbook is organised into four progressive versions, each separated by a divider tab:
B11: Version | C11: Divider Tab | D11: Description | E11: Sheets
B12: v1 — Simple Model | C12: Simple Model → | D12: The foundation case. A 3-year insurance contract with 1,000 in premiums collected upfront, 600 in expected claims, 150 in expected expenses, and a 90 Risk Adjustment — all at nominal value (0% discount rate). The CSM of 160 represents the unearned profit and is released evenly over 3 years. Claims and expenses are symmetric each period, so there is no experience variance. This version establishes the core IFRS 17 mechanics: no Day 1 profit (premiums create equal entries on asset and liability sides), and revenue emerges over time as the liability is released to the P&L. | E12: Assumptions (v1), P&L (v1), Balance Sheet (v1), Cash Flow (v1)
B13: v2 — Add Discounting | C13: Add discounting → | D13: Builds on v1 by introducing a yield curve to discount future cash flows to present value. The BEL drops from 750 (nominal) to ~698 (discounted), which increases the CSM to ~212. Each period, the BEL and CSM accrete interest (discount unwind), and the model tracks BEL rollforward components: opening balance, expected outflow releases, accretion, and discount rate changes. Insurance finance income/expense flows entirely through P&L (no OCI election). This version shows how time value of money affects profit emergence and liability measurement. | E13: Assumptions (v2), P&L (v2), Balance Sheet (v2), Cash Flow (v2)
B14: v3a — Experience Variance (no re-estimation) | C14: Experience Variance → | D14: Introduces a real-world complication: actual claims of 250/year exceed the expected 200/year, creating a 50/year experience variance. Critically, the insurer does NOT revise its future assumptions — it treats each year's overrun as a one-off. The BEL rollforward and CSM rollforward remain identical to v2 (since expectations are unchanged), but the P&L shows higher incurred claims, reducing net profit. This version isolates the impact of experience variance on the income statement without any feedback into the liability measurement. Compare with v3b to see how the same actual experience leads to very different financial statements depending on the re-estimation decision. | E14: Assumptions (v3a), P&L (v3a), Balance Sheet (v3a), Cash Flow (v3a)
B15: v3b — Experience Variance (with re-estimation) | C15: Re-estimation (Option B) → | D15: Same actual cash flows as v3a — Year 1 claims are 250 vs. 200 expected — but here the insurer re-estimates future claims upward to 250/year for Years 2 and 3. This creates a BEL increase of ~95 at end of Year 1 (the present value of the additional 50/year for two remaining years). Under IFRS 17, this BEL increase is absorbed by the CSM — reducing it from ~145 to ~82 — rather than hitting the P&L immediately (since the contract is not onerous). The CSM release in subsequent years is therefore lower, spreading the impact of adverse experience over the remaining coverage period. Compare with v3a to see how the re-estimation decision shifts profit timing. | E15: Assumptions (v3b), P&L (v3b), Balance Sheet (v3b), Cash Flow (v3b)
B16: v4 — Onerous Contract (Loss Component) | C16: Onerous Contract → | D16: Takes the re-estimation concept from v3b to its extreme: actual claims are 400/year (double the expected 200), and the insurer re-estimates at end of Year 1. The BEL increase of ~381 far exceeds the available CSM of ~218, exhausting it completely. Under IFRS 17 paragraph 48, the excess of ~163 is recognised as an immediate loss in the P&L, and a Loss Component is established within the liability. In Years 2 and 3, no CSM is released (it’s zero), so the only “profit” is the RA release. The Loss Component is released proportionally as revised expected outflows occur. This version shows the asymmetric treatment of good and bad news: profits are deferred (CSM), but losses are recognised immediately. | E16: Assumptions (v4), P&L (v4), Balance Sheet (v4), Cash Flow (v4)
B17: v5 — Reinsurance Held (Quota Share) | C17: Reinsurance Held → | D17: Builds on v2 by adding a 20% proportional quota share reinsurance contract. The cedant pays 200 to the reinsurer (20% of 1,000 gross premium) and receives 20% of all claims and expenses as recoveries. A Reinsurance Contract Asset appears on the balance sheet alongside the existing Insurance Contract Liability. The asset has its own building blocks: Ceded BEL (PV of expected recoveries), Ceded RA (risk transferred to reinsurer), and a Reinsurance CSM (net cost of reinsurance, which is released as an expense over the coverage period). The P&L shows gross insurance revenue/expense AND reinsurance income/expense side by side, with net income exactly 80% of v2 — demonstrating the proportional nature of quota share reinsurance. | E17: Assumptions (v5), P&L (v5), Balance Sheet (v5), Cash Flow (v5)
B18: KEY FEATURES
B19: • Each version contains a full set of Assumptions, P&L, Balance Sheet, and Cash Flow sheets
B20: • Coloured divider tabs separate the versions for easy navigation
B21: • All financial statements are fully linked — changes in assumptions flow through automatically
B22: • The Cash Flow Reconciliation ties Balance Sheet cash movements to P&L and liability changes
B23: • Assets consist solely of cash (no investment portfolio)
B25: HOW TO USE
B26: Start with Version 1 to master the building blocks (BEL, RA, CSM) and the core revenue recognition mechanics. Move to Version 2 to understand how discounting changes liability measurement, profit emergence, and introduces accretion. Then compare Versions 3 and 4 side by side: they share the same actual cash flows but differ in whether the insurer re-estimates future assumptions — this contrast highlights the critical accounting policy choice and its impact on profit timing. In each version, compare the Assumptions tab to the prior version to see exactly what changed.
B29: Created by Francisco Martinez Checa — April 2026
B30: pacomc999@gmail.com

Sheet Simple Model →
A1: ← Simple / toy model tabs are to the right of this divider

Sheet Assumptions (v1)
A1: IFRS 17 — Simple Insurance Example
A2: Simplifications:
A3: • No discounting (0% discount rate) — all cash flows at nominal value
A4: • Assets consist solely of cash (no investment portfolio or investment income)
A5: • Claims and expenses are equal each year (symmetric risk profile)
A6: • Risk Adjustment released linearly over the coverage period
A8: Contract Details
A9: Coverage period (years) | B9: 3
A10: Discount rate | B10: 0
A12: Cash Flows at Inception | B12: Total | C12: Per Year
A13: Premiums collected (upfront) | B13: 1000
A14: Expected claims | B14: 600 | C14: =B14/B9 -> 200
A15: Expected expenses | B15: 150 | C15: =B15/B9 -> 50
A16: Risk Adjustment (total) | B16: 90 | C16: =B16/B9 -> 30
A18: Building Blocks at Inception
A19: BEL (Best Estimate Liability) | B19: =B14+B15 -> 750
A20: Risk Adjustment | B20: =B16 -> 90
A21: Contractual Service Margin (CSM) | B21: =B13-B19-B16 -> 160
A22: Total Insurance Liability at Inception | B22: =B19+B20+B21 -> 1000
A24: Release Pattern
A25: CSM release per year | B25: =B21/B9 -> 53.333333
A26: RA release per year | B26: =B16/B9 -> 30
A28: How it works:
A29: 1. The premium creates a balanced entry: cash +1,000 on the asset side and insurance liability +1,000 on the liability side
A30: The CSM acts as the plug that forces Day 1 profit to zero (Liability = BEL + RA + CSM = Premium)
A31: 2. Revenue then emerges over the coverage period as the liability components (BEL, RA, CSM) are released to the P&L
A32: 3. The CSM is the 'unearned profit' — it smooths profit recognition over the coverage period
A33: 4. In this version, actual claims = expected claims each year

Sheet P&L (v1)
A1: INCOME STATEMENT (P&L)
A2: Insurance Company — IFRS 17 Example
C4: 46022 | D4: 46387 | E4: 46752
A5: INSURANCE REVENUE
A6: BEL release — expected claims | C6: ='Assumptions (v1)'!C14 -> 200 | D6: ='Assumptions (v1)'!C14 -> 200 | E6: ='Assumptions (v1)'!C14 -> 200
A7: BEL release — expected expenses | C7: ='Assumptions (v1)'!C15 -> 50 | D7: ='Assumptions (v1)'!C15 -> 50 | E7: ='Assumptions (v1)'!C15 -> 50
A8: Risk Adjustment release | C8: ='Assumptions (v1)'!B26 -> 30 | D8: ='Assumptions (v1)'!B26 -> 30 | E8: ='Assumptions (v1)'!B26 -> 30
A9: CSM release (earned profit) | C9: ='Assumptions (v1)'!B25 -> 53.333333 | D9: ='Assumptions (v1)'!B25 -> 53.333333 | E9: ='Assumptions (v1)'!B25 -> 53.333333
A11: Total Insurance Revenue | C11: =SUM(C6:C9) -> 333.33333 | D11: =SUM(D6:D9) -> 333.33333 | E11: =SUM(E6:E9) -> 333.33333
A13: INSURANCE SERVICE EXPENSE
A14: Actual claims incurred | C14: ='Assumptions (v1)'!C14 -> 200 | D14: ='Assumptions (v1)'!C14 -> 200 | E14: ='Assumptions (v1)'!C14 -> 200
A15: Actual expenses incurred | C15: ='Assumptions (v1)'!C15 -> 50 | D15: ='Assumptions (v1)'!C15 -> 50 | E15: ='Assumptions (v1)'!C15 -> 50
A17: Total Insurance Service Expense | C17: =-(C14+C15) -> -250 | D17: =-(D14+D15) -> -250 | E17: =-(E14+E15) -> -250
B18: =B15+B16+B17 -> 0
A19: Cash outflows (for BS link) | C19: Year 1 | D19: Year 2 | E19: Year 3
A20: Total cash paid out (claims + expenses) | C20: ='Assumptions (v1)'!C14+'Assumptions (v1)'!C15 -> 250 | D20: ='Assumptions (v1)'!C14+'Assumptions (v1)'!C15 -> 250 | E20: ='Assumptions (v1)'!C14+'Assumptions (v1)'!C15 -> 250
A22: INSURANCE SERVICE RESULT | C22: =C11+C17 -> 83.333333 | D22: =D11+D17 -> 83.333333 | E22: =E11+E17 -> 83.333333
A24: Net Income | C24: =C22 -> 83.333333 | D24: =D22 -> 83.333333 | E24: =E22 -> 83.333333
A26: Cumulative Profit | C26: =C24 -> 83.333333 | D26: =C26+D24 -> 166.66667 | E26: =D26+E24 -> 250
A28: KEY INSIGHT:
A29: Revenue ≠ Premiums! Revenue = expected costs released + RA released + CSM released
A30: The CSM release (53.3/yr) + RA release (30/yr) = 83.3 profit per year
A31: Total profit over 3 years = 250 = CSM (160) + RA (90) = Premium (1,000) - Claims (600) - Expenses (150)

Sheet Balance Sheet (v1)
A1: BALANCE SHEET
A2: Insurance Company — IFRS 17 Example
B4: 45658 | C4: 46022 | D4: 46387 | E4: 46752
A5: ASSETS
A6: Cash & Investments | B6: ='Assumptions (v1)'!B13 -> 1000 | C6: =B6-'P&L (v1)'!C20 -> 750 | D6: =C6-'P&L (v1)'!D20 -> 500 | E6: =D6-'P&L (v1)'!E20 -> 250
A7: Total Assets | B7: =B6 -> 1000 | C7: =C6 -> 750 | D7: =D6 -> 500 | E7: =E6 -> 250
A9: LIABILITIES
A10: Insurance Contract Liability:
A11: BEL (Best Estimate Liability) | B11: ='Assumptions (v1)'!B19 -> 750 | C11: =B11-'P&L (v1)'!C6-'P&L (v1)'!C7 -> 500 | D11: =C11-'P&L (v1)'!D6-'P&L (v1)'!D7 -> 250 | E11: =D11-'P&L (v1)'!E6-'P&L (v1)'!E7 -> 0
A12: Risk Adjustment | B12: ='Assumptions (v1)'!B20 -> 90 | C12: =B12-'P&L (v1)'!C8 -> 60 | D12: =C12-'P&L (v1)'!D8 -> 30 | E12: =D12-'P&L (v1)'!E8 -> 0
A13: Fulfilment Cash Flows (BEL + RA) | B13: =B11+B12 -> 840 | C13: =C11+C12 -> 560 | D13: =D11+D12 -> 280 | E13: =E11+E12 -> 0
A14: Contractual Service Margin (CSM) | B14: ='Assumptions (v1)'!B21 -> 160 | C14: =B14-'P&L (v1)'!C9 -> 106.66667 | D14: =C14-'P&L (v1)'!D9 -> 53.333333 | E14: =D14-'P&L (v1)'!E9 -> 0
A15: Total Insurance Liability | B15: =B11+B12+B14 -> 1000 | C15: =C11+C12+C14 -> 666.66667 | D15: =D11+D12+D14 -> 333.33333 | E15: =E11+E12+E14 -> 0
A16: Total Liabilities | B16: =B15 -> 1000 | C16: =C15 -> 666.66667 | D16: =D15 -> 333.33333 | E16: =E15 -> 0
A18: EQUITY
A19: Retained Earnings | B19: 0 | C19: =B19+'P&L (v1)'!C24 -> 83.333333 | D19: =C19+'P&L (v1)'!D24 -> 166.66667 | E19: =D19+'P&L (v1)'!E24 -> 250
A20: Total Equity | B20: =B19 -> 0 | C20: =C19 -> 83.333333 | D20: =D19 -> 166.66667 | E20: =E19 -> 250
A22: CHECK: Assets = Liabilities + Equity | B22: =IF(ABS(B7-B16-B20)<0.01,"✅ Balanced","❌ Error") -> ✅ Balanced | C22: =IF(ABS(C7-C16-C20)<0.01,"✅ Balanced","❌ Error") -> ✅ Balanced | D22: =IF(ABS(D7-D16-D20)<0.01,"✅ Balanced","❌ Error") -> ✅ Balanced | E22: =IF(ABS(E7-E16-E20)<0.01,"✅ Balanced","❌ Error") -> ✅ Balanced

Sheet Cash Flow (v1)
A1: CASH FLOW RECONCILIATION
A2: Ties Balance Sheet cash movement to P&L and liability changes
C4: 46022 | D4: 46387 | E4: 46752
A6: Opening Cash | C6: ='Balance Sheet (v1)'!B6 -> 1000 | D6: ='Balance Sheet (v1)'!C6 -> 750 | E6: ='Balance Sheet (v1)'!D6 -> 500
A8: Cash outflows:
A9: Claims paid | C9: =-'Assumptions (v1)'!C14 -> -200 | D9: =-'Assumptions (v1)'!C14 -> -200 | E9: =-'Assumptions (v1)'!C14 -> -200
A10: Expenses paid | C10: =-'Assumptions (v1)'!C15 -> -50 | D10: =-'Assumptions (v1)'!C15 -> -50 | E10: =-'Assumptions (v1)'!C15 -> -50
A11: Total Cash Outflows | C11: =SUM(C9:C10) -> -250 | D11: =SUM(D9:D10) -> -250 | E11: =SUM(E9:E10) -> -250
A13: Closing Cash | C13: =C6+C11 -> 750 | D13: =D6+D11 -> 500 | E13: =E6+E11 -> 250
A15: CHECK: Ties to Balance Sheet | C15: =IF(ABS(C13-'Balance Sheet (v1)'!C6)<0.01,"✅ Ties","❌ Error") -> ✅ Ties | D15: =IF(ABS(D13-'Balance Sheet (v1)'!D6)<0.01,"✅ Ties","❌ Error") -> ✅ Ties | E15: =IF(ABS(E13-'Balance Sheet (v1)'!E6)<0.01,"✅ Ties","❌ Error") -> ✅ Ties
A18: LIABILITY ROLLFORWARD | B18: =B15+B16+B17 -> 0
A19: Shows how the insurance liability changes each year
C20: Year 1 | D20: Year 2 | E20: Year 3
A22: Opening Liability | C22: ='Balance Sheet (v1)'!B15 -> 1000 | D22: ='Balance Sheet (v1)'!C15 -> 666.66667 | E22: ='Balance Sheet (v1)'!D15 -> 333.33333
A24: Releases to P&L (reduce liability):
A25: BEL release (expected costs) | C25: =-('P&L (v1)'!C6+'P&L (v1)'!C7) -> -250 | D25: =-('P&L (v1)'!D6+'P&L (v1)'!D7) -> -250 | E25: =-('P&L (v1)'!E6+'P&L (v1)'!E7) -> -250
A26: Risk Adjustment release | C26: =-'P&L (v1)'!C8 -> -30 | D26: =-'P&L (v1)'!D8 -> -30 | E26: =-'P&L (v1)'!E8 -> -30
A27: CSM release | C27: =-'P&L (v1)'!C9 -> -53.333333 | D27: =-'P&L (v1)'!D9 -> -53.333333 | E27: =-'P&L (v1)'!E9 -> -53.333333
A28: Total Liability Release | C28: =SUM(C25:C27) -> -333.33333 | D28: =SUM(D25:D27) -> -333.33333 | E28: =SUM(E25:E27) -> -333.33333
A30: Closing Liability | C30: =C22+C28 -> 666.66667 | D30: =D22+D28 -> 333.33333 | E30: =E22+E28 -> 0
A32: CHECK: Ties to Balance Sheet | C32: =IF(ABS(C30-'Balance Sheet (v1)'!C15)<0.01,"✅ Ties","❌ Error") -> ✅ Ties | D32: =IF(ABS(D30-'Balance Sheet (v1)'!D15)<0.01,"✅ Ties","❌ Error") -> ✅ Ties | E32: =IF(ABS(E30-'Balance Sheet (v1)'!E15)<0.01,"✅ Ties","❌ Error") -> ✅ Ties
A34: KEY CONNECTION:
A35: Liability release (333.3) = Insurance Revenue (333.3) on P&L
A36: Of which: 250 covers costs (claims+expenses), leaving 83.3 as profit (CSM + RA release)
A37: Cash out (250/yr) ≠ Revenue (333.3/yr) — this is the key IFRS 17 difference!

Sheet Add discounting →

Sheet Assumptions (v2)
A1: IFRS 17 — Example with discounting
A2: Simplifications:
A3: • Assets consist solely of cash (no investment portfolio or investment income)
A4: • All insurance finance income/expense flows through P&L (no OCI election)
A5: • Claims and expenses are equal each year; RA released linearly
A7: CONTRACT DETAILS
A8: Coverage period (years) | C8: 3
A9: Premiums collected (upfront) | C9: 1000
A11: UNDISCOUNTED CASH FLOWS | C11: Total | D11: 46022 | E11: 46387 | F11: 46752
A12: Expected claims | C12: 600 | D12: =C12/C8 -> 200 | E12: =C12/C8 -> 200 | F12: =C12/C8 -> 200
A13: Expected expenses | C13: 150 | D13: =C13/C8 -> 50 | E13: =C13/C8 -> 50 | F13: =C13/C8 -> 50
A14: Total undiscounted outflows | C14: =C12+C13 -> 750 | D14: =D12+D13 -> 250 | E14: =E12+E13 -> 250 | F14: =F12+F13 -> 250
A15: Risk Adjustment (total, undiscounted) | C15: 90
A17: YIELD CURVE (Spot Rates) | D17: 1Y Spot | E17: 2Y Spot | F17: 3Y Spot
A18: Curve at Inception (t=0) | C18: ← blue = input | D18: 0.03 | E18: 0.035 | F18: 0.04
A19: Curve at End Year 1 (t=1) | D19: 0.03 | E19: 0.035
A20: Curve at End Year 2 (t=2) | D20: 0.03
A22: DISCOUNT FACTORS | D22: DF 1Y | E22: DF 2Y | F22: DF 3Y
A23: DFs at Inception (t=0) | D23: =1/(1+D18)^1 -> 0.97087379 | E23: =1/(1+E18)^2 -> 0.9335107 | F23: =1/(1+F18)^3 -> 0.88899636
A24: DFs at End Year 1 (t=1) | D24: =1/(1+D19)^1 -> 0.97087379 | E24: =1/(1+E19)^2 -> 0.9335107
A25: DFs at End Year 2 (t=2) | D25: =1/(1+D20)^1 -> 0.97087379
A27: BEL (DISCOUNTED) AT EACH DATE | D27: PV of Y1 CFs | E27: PV of Y2 CFs | F27: PV of Y3 CFs | G27: BEL Total
A28: BEL at Inception (t=0) | D28: =D14*D23 -> 242.71845 | E28: =E14*E23 -> 233.37768 | F28: =F14*F23 -> 222.24909 | G28: =SUM(D28:F28) -> 698.34521
A29: BEL at End Year 1 (t=1) — using NEW curve | E29: =E14*D24 -> 242.71845 | F29: =F14*E24 -> 233.37768 | G29: =SUM(E29:F29) -> 476.09612
A30: BEL at End Year 2 (t=2) — using NEW curve | F30: =F14*D25 -> 242.71845 | G30: =F30 -> 242.71845
A31: BEL at End Year 3 (t=3) | G31: 0
A33: BEL at End Year 1 — using OLD curve (for accretion calc) | E33: =E14*D23 -> 242.71845 | F33: =F14*E23 -> 233.37768 | G33: =SUM(E33:F33) -> 476.09612
A34: BEL at End Year 2 — using OLD curve (for accretion calc) | F34: =F14*D23 -> 242.71845 | G34: =F34 -> 242.71845
A36: BEL ROLLFORWARD COMPONENTS | D36: 46022 | E36: 46387 | F36: 46752
A37: Opening BEL | D37: =G28 -> 698.34521 | E37: =G29 -> 476.09612 | F37: =G30 -> 242.71845
A38: Less: BEL release (expected outflows for the year) | D38: =-D14 -> -250 | E38: =-E14 -> -250 | F38: =-F14 -> -250
A39: Accretion (discount unwind) | D39: =G33-(G28-D14) -> 27.75091 | E39: =G34-(G29-E14) -> 16.622325 | F39: =G31-(G30-F14) -> 7.2815534
A40: Effect of discount rate changes | D40: =G29-G33 -> 0 | E40: =G30-G34 -> 0 | F40: 0
A41: Closing BEL | D41: =SUM(D37:D40) -> 476.09612 | E41: =SUM(E37:E40) -> 242.71845 | F41: =SUM(F37:F40) -> 0
A42: CHECK: Closing BEL ties to BEL calc above | D42: =IF(ABS(D41-G29)<0.01,"✅","❌") -> ✅ | E42: =IF(ABS(E41-G30)<0.01,"✅","❌") -> ✅ | F42: =IF(ABS(F41-G31)<0.01,"✅","❌") -> ✅
A44: RISK ADJUSTMENT
A45: RA at Inception | C45: =C15 -> 90
A46: RA release per year (evenly over coverage) | C46: =C45/C8 -> 30
A48: BUILDING BLOCKS AT INCEPTION
A49: BEL (discounted) | C49: =G28 -> 698.34521
...

Sheet Balance Sheet (v2)
A1: BALANCE SHEET
A2: IFRS 17 — Enhanced Model with Discounting
B4: 45658 | C4: 46022 | D4: 46387 | E4: 46752
A5: ASSETS
A6: Cash & Investments | B6: ='Assumptions (v2)'!C9 -> 1000 | C6: =B6-'P&L (v2)'!C32 -> 750 | D6: =C6-'P&L (v2)'!D32 -> 500 | E6: =D6-'P&L (v2)'!E32 -> 250
A7: Total Assets | B7: =B6 -> 1000 | C7: =C6 -> 750 | D7: =D6 -> 500 | E7: =E6 -> 250
A9: LIABILITIES
A10: Insurance Contract Liability:
A11: BEL (Best Estimate Liability) | B11: ='Assumptions (v2)'!G28 -> 698.34521 | C11: ='Assumptions (v2)'!G29 -> 476.09612 | D11: ='Assumptions (v2)'!G30 -> 242.71845 | E11: ='Assumptions (v2)'!G31 -> 0
A12: Risk Adjustment | B12: ='Assumptions (v2)'!C50 -> 90 | C12: =B12-'P&L (v2)'!C8 -> 60 | D12: =C12-'P&L (v2)'!D8 -> 30 | E12: =D12-'P&L (v2)'!E8 -> 0
A13: Fulfilment Cash Flows (BEL + RA) | B13: =B11+B12 -> 788.34521 | C13: =C11+C12 -> 536.09612 | D13: =D11+D12 -> 272.71845 | E13: =E11+E12 -> 0
A14: Contractual Service Margin (CSM) | B14: ='Assumptions (v2)'!C52 -> 211.65479 | C14: ='Assumptions (v2)'!D60 -> 145.33629 | D14: ='Assumptions (v2)'!E60 -> 74.848188 | E14: ='Assumptions (v2)'!F60 -> 0
A15: Total Insurance Liability | B15: =B13+B14 -> 1000 | C15: =C13+C14 -> 681.43241 | D15: =D13+D14 -> 347.56664 | E15: =E13+E14 -> 0
A16: Total Liabilities | B16: =B15 -> 1000 | C16: =C15 -> 681.43241 | D16: =D15 -> 347.56664 | E16: =E15 -> 0
A18: EQUITY
A19: Retained Earnings | B19: 0 | C19: =B19+'P&L (v2)'!C27 -> 68.56759 | D19: =C19+'P&L (v2)'!D27 -> 152.43336 | E19: =D19+'P&L (v2)'!E27 -> 250
A20: Total Equity | B20: =B19 -> 0 | C20: =C19 -> 68.56759 | D20: =D19 -> 152.43336 | E20: =E19 -> 250
A22: CHECK: Assets = Liabilities + Equity | B22: =IF(ABS(B7-B16-B20)<0.01,"✅ Balanced","❌ "&TEXT(B7-B16-B20,"#,##0.00")) -> ✅ Balanced | C22: =IF(ABS(C7-C16-C20)<0.01,"✅ Balanced","❌ "&TEXT(C7-C16-C20,"#,##0.00")) -> ✅ Balanced | D22: =IF(ABS(D7-D16-D20)<0.01,"✅ Balanced","❌ "&TEXT(D7-D16-D20,"#,##0.00")) -> ✅ Balanced | E22: =IF(ABS(E7-E16-E20)<0.01,"✅ Balanced","❌ "&TEXT(E7-E16-E20,"#,##0.00")) -> ✅ Balanced

Sheet P&L (v2)
A1: INCOME STATEMENT (P&L)
A2: IFRS 17 — Enhanced Model with Discounting
C4: 46022 | D4: 46387 | E4: 46752
A5: INSURANCE REVENUE
A6: BEL release — expected claims | C6: ='Assumptions (v2)'!D12 -> 200 | D6: ='Assumptions (v2)'!E12 -> 200 | E6: ='Assumptions (v2)'!F12 -> 200
A7: BEL release — expected expenses | C7: ='Assumptions (v2)'!D13 -> 50 | D7: ='Assumptions (v2)'!E13 -> 50 | E7: ='Assumptions (v2)'!F13 -> 50
A8: Risk Adjustment release | C8: ='Assumptions (v2)'!C46 -> 30 | D8: ='Assumptions (v2)'!C46 -> 30 | E8: ='Assumptions (v2)'!C46 -> 30
A9: CSM release (earned profit) | C9: =-'Assumptions (v2)'!D59 -> 72.668144 | D9: =-'Assumptions (v2)'!E59 -> 74.848188 | E9: =-'Assumptions (v2)'!F59 -> 77.093634
A11: Total Insurance Revenue | C11: =SUM(C6:C9) -> 352.66814 | D11: =SUM(D6:D9) -> 354.84819 | E11: =SUM(E6:E9) -> 357.09363
A13: INSURANCE SERVICE EXPENSE
A14: Actual claims incurred | C14: ='Assumptions (v2)'!D12 -> 200 | D14: ='Assumptions (v2)'!E12 -> 200 | E14: ='Assumptions (v2)'!F12 -> 200
A15: Actual expenses incurred | C15: ='Assumptions (v2)'!D13 -> 50 | D15: ='Assumptions (v2)'!E13 -> 50 | E15: ='Assumptions (v2)'!F13 -> 50
A17: Total Insurance Service Expense | C17: =-(C14+C15) -> -250 | D17: =-(D14+D15) -> -250 | E17: =-(E14+E15) -> -250
A19: INSURANCE SERVICE RESULT | C19: =C11+C17 -> 102.66814 | D19: =D11+D17 -> 104.84819 | E19: =E11+E17 -> 107.09363
A21: INSURANCE FINANCE INCOME / (EXPENSE)
A22: Accretion of BEL (discount unwind) | C22: =-'Assumptions (v2)'!D39 -> -27.75091 | D22: =-'Assumptions (v2)'!E39 -> -16.622325 | E22: =-'Assumptions (v2)'!F39 -> -7.2815534
A23: Effect of discount rate changes | C23: =-'Assumptions (v2)'!D40 -> 0 | D23: =-'Assumptions (v2)'!E40 -> 0 | E23: =-'Assumptions (v2)'!F40 -> 0
A24: Accretion of CSM | C24: =-'Assumptions (v2)'!D57 -> -6.3496437 | D24: =-'Assumptions (v2)'!E57 -> -4.3600886 | E24: =-'Assumptions (v2)'!F57 -> -2.2454457
A25: Total Insurance Finance Income / (Expense) | C25: =SUM(C22:C24) -> -34.100554 | D25: =SUM(D22:D24) -> -20.982414 | E25: =SUM(E22:E24) -> -9.5269991
A27: NET INCOME | C27: =C19+C25 -> 68.56759 | D27: =D19+D25 -> 83.865775 | E27: =E19+E25 -> 97.566635
A29: Cumulative Profit | C29: =C27 -> 68.56759 | D29: =C29+D27 -> 152.43336 | E29: =D29+E27 -> 250
A31: Cash outflows (for BS link)
A32: Total cash paid out (claims + expenses) | C32: ='Assumptions (v2)'!D14 -> 250 | D32: ='Assumptions (v2)'!E14 -> 250 | E32: ='Assumptions (v2)'!F14 -> 250

Sheet Cash Flow (v2)
A1: CASH FLOW RECONCILIATION
A2: Ties Balance Sheet cash movement to P&L and liability changes
C4: 46022 | D4: 46387 | E4: 46752
A6: Opening Cash | C6: ='Balance Sheet (v2)'!B6 -> 1000 | D6: ='Balance Sheet (v2)'!C6 -> 750 | E6: ='Balance Sheet (v2)'!D6 -> 500
A8: Cash outflows:
A9: Claims paid | C9: =-'Assumptions (v2)'!D12 -> -200 | D9: =-'Assumptions (v2)'!E12 -> -200 | E9: =-'Assumptions (v2)'!F12 -> -200
A10: Expenses paid | C10: =-'Assumptions (v2)'!D13 -> -50 | D10: =-'Assumptions (v2)'!E13 -> -50 | E10: =-'Assumptions (v2)'!F13 -> -50
A11: Total Cash Outflows | C11: =SUM(C9:C10) -> -250 | D11: =SUM(D9:D10) -> -250 | E11: =SUM(E9:E10) -> -250
A13: Closing Cash | C13: =C6+C11 -> 750 | D13: =D6+D11 -> 500 | E13: =E6+E11 -> 250
A15: CHECK: Ties to Balance Sheet | C15: =IF(ABS(C13-'Balance Sheet (v2)'!C6)<0.01,"✅ Ties","❌ "&TEXT(C13-'Balance Sheet (v2)'!C6,"#,##0.00")) -> ✅ Ties | D15: =IF(ABS(D13-'Balance Sheet (v2)'!D6)<0.01,"✅ Ties","❌ "&TEXT(D13-'Balance Sheet (v2)'!D6,"#,##0.00")) -> ✅ Ties | E15: =IF(ABS(E13-'Balance Sheet (v2)'!E6)<0.01,"✅ Ties","❌ "&TEXT(E13-'Balance Sheet (v2)'!E6,"#,##0.00")) -> ✅ Ties
A18: LIABILITY ROLLFORWARD
A19: Shows how the insurance liability changes each year
C20: Year 1 | D20: Year 2 | E20: Year 3
A22: Opening Liability | C22: ='Balance Sheet (v2)'!B15 -> 1000 | D22: ='Balance Sheet (v2)'!C15 -> 681.43241 | E22: ='Balance Sheet (v2)'!D15 -> 347.56664
A24: Releases to P&L (reduce liability):
A25: BEL release (expected costs) | C25: =-('P&L (v2)'!C6+'P&L (v2)'!C7) -> -250 | D25: =-('P&L (v2)'!D6+'P&L (v2)'!D7) -> -250 | E25: =-('P&L (v2)'!E6+'P&L (v2)'!E7) -> -250
A26: Risk Adjustment release | C26: =-'P&L (v2)'!C8 -> -30 | D26: =-'P&L (v2)'!D8 -> -30 | E26: =-'P&L (v2)'!E8 -> -30
A27: CSM release | C27: =-'P&L (v2)'!C9 -> -72.668144 | D27: =-'P&L (v2)'!D9 -> -74.848188 | E27: =-'P&L (v2)'!E9 -> -77.093634
A28: Total Releases | C28: =SUM(C25:C27) -> -352.66814 | D28: =SUM(D25:D27) -> -354.84819 | E28: =SUM(E25:E27) -> -357.09363
A30: Insurance Finance (increase liability):
A31: BEL accretion (discount unwind) | C31: ='Assumptions (v2)'!D39 -> 27.75091 | D31: ='Assumptions (v2)'!E39 -> 16.622325 | E31: ='Assumptions (v2)'!F39 -> 7.2815534
A32: Effect of discount rate changes | C32: ='Assumptions (v2)'!D40 -> 0 | D32: ='Assumptions (v2)'!E40 -> 0 | E32: ='Assumptions (v2)'!F40 -> 0
A33: CSM accretion | C33: ='Assumptions (v2)'!D57 -> 6.3496437 | D33: ='Assumptions (v2)'!E57 -> 4.3600886 | E33: ='Assumptions (v2)'!F57 -> 2.2454457
A34: Total Insurance Finance | C34: =SUM(C31:C33) -> 34.100554 | D34: =SUM(D31:D33) -> 20.982414 | E34: =SUM(E31:E33) -> 9.5269991
A36: Closing Liability | C36: =C22+C28+C34 -> 681.43241 | D36: =D22+D28+D34 -> 347.56664 | E36: =E22+E28+E34 -> 2.1316282e-14
A38: CHECK: Ties to Balance Sheet | C38: =IF(ABS(C36-'Balance Sheet (v2)'!C15)<0.01,"✅ Ties","❌ "&TEXT(C36-'Balance Sheet (v2)'!C15,"#,##0.00")) -> ✅ Ties | D38: =IF(ABS(D36-'Balance Sheet (v2)'!D15)<0.01,"✅ Ties","❌ "&TEXT(D36-'Balance Sheet (v2)'!D15,"#,##0.00")) -> ✅ Ties | E38: =IF(ABS(E36-'Balance Sheet (v2)'!E15)<0.01,"✅ Ties","❌ "&TEXT(E36-'Balance Sheet (v2)'!E15,"#,##0.00")) -> ✅ Ties

Sheet Experience Variance →

Sheet Assumptions (v3a)
A1: IFRS 17 — Experience Variance (Option A)
A2: Simplifications:
A3: • Actual claims exceed expected, but insurer does NOT re-estimate future claims
A4: • Assets consist solely of cash (no investment portfolio or investment income)
A5: • All insurance finance income/expense flows through P&L (no OCI election)
A7: CONTRACT DETAILS
A8: Coverage period (years) | C8: 3
A9: Premiums collected (upfront) | C9: 1000
A11: EXPECTED CASH FLOWS (at inception) | C11: Total | D11: 46022 | E11: 46387 | F11: 46752
A12: Expected claims | C12: 600 | D12: =C12/C8 -> 200 | E12: =C12/C8 -> 200 | F12: =C12/C8 -> 200
A13: Expected expenses | C13: 150 | D13: =C13/C8 -> 50 | E13: =C13/C8 -> 50 | F13: =C13/C8 -> 50
A14: Total expected undiscounted outflows | C14: =C12+C13 -> 750 | D14: =D12+D13 -> 250 | E14: =E12+E13 -> 250 | F14: =F12+F13 -> 250
A15: Risk Adjustment (total, undiscounted) | C15: 90
A17: ACTUAL CASH FLOWS | D17: 46022 | E17: 46387 | F17: 46752
A18: Actual claims | D18: 250 | E18: 250 | F18: 250
A19: Actual expenses | D19: =D13 -> 50 | E19: =E13 -> 50 | F19: =F13 -> 50
A20: Total actual outflows | D20: =D18+D19 -> 300 | E20: =E18+E19 -> 300 | F20: =F18+F19 -> 300
A22: YIELD CURVE (Spot Rates) | D22: 1Y Spot | E22: 2Y Spot | F22: 3Y Spot
A23: Curve at Inception (t=0) | C23: ← blue = input | D23: 0.03 | E23: 0.035 | F23: 0.04
A24: Curve at End Year 1 (t=1) | D24: 0.03 | E24: 0.035
A25: Curve at End Year 2 (t=2) | D25: 0.03
A27: DISCOUNT FACTORS | D27: DF 1Y | E27: DF 2Y | F27: DF 3Y
A28: DFs at Inception (t=0) | D28: =1/(1+D23)^1 -> 0.97087379 | E28: =1/(1+E23)^2 -> 0.9335107 | F28: =1/(1+F23)^3 -> 0.88899636
A29: DFs at End Year 1 (t=1) | D29: =1/(1+D24)^1 -> 0.97087379 | E29: =1/(1+E24)^2 -> 0.9335107
A30: DFs at End Year 2 (t=2) | D30: =1/(1+D25)^1 -> 0.97087379
A32: BEL (DISCOUNTED) AT EACH DATE | D32: PV of Y1 CFs | E32: PV of Y2 CFs | F32: PV of Y3 CFs | G32: BEL Total
A33: BEL at Inception (t=0) | D33: =D14*D28 -> 242.71845 | E33: =E14*E28 -> 233.37768 | F33: =F14*F28 -> 222.24909 | G33: =SUM(D33:F33) -> 698.34521
A34: BEL at End Year 1 (t=1) — using NEW curve | E34: =E14*D29 -> 242.71845 | F34: =F14*E29 -> 233.37768 | G34: =SUM(E34:F34) -> 476.09612
A35: BEL at End Year 2 (t=2) — using NEW curve | F35: =F14*D30 -> 242.71845 | G35: =F35 -> 242.71845
A36: BEL at End Year 3 (t=3) | G36: 0
A38: BEL at End Year 1 — using OLD curve (for accretion calc) | E38: =E14*D28 -> 242.71845 | F38: =F14*E28 -> 233.37768 | G38: =SUM(E38:F38) -> 476.09612
A39: BEL at End Year 2 — using OLD curve (for accretion calc) | F39: =F14*D28 -> 242.71845 | G39: =F39 -> 242.71845
A41: BEL ROLLFORWARD COMPONENTS | D41: 46022 | E41: 46387 | F41: 46752
A42: Opening BEL | D42: =G33 -> 698.34521 | E42: =G34 -> 476.09612 | F42: =G35 -> 242.71845
A43: Less: BEL release (expected outflows for the year) | D43: =-D14 -> -250 | E43: =-E14 -> -250 | F43: =-F14 -> -250
A44: Accretion (discount unwind) | D44: =G38-(G33-D14) -> 27.75091 | E44: =G39-(G34-E14) -> 16.622325 | F44: =G36-(G35-F14) -> 7.2815534
A45: Effect of discount rate changes | D45: =G34-G38 -> 0 | E45: =G35-G39 -> 0 | F45: 0
A46: Closing BEL | D46: =SUM(D42:D45) -> 476.09612 | E46: =SUM(E42:E45) -> 242.71845 | F46: =SUM(F42:F45) -> 0
A47: CHECK: Closing BEL ties to BEL calc above | D47: =IF(ABS(D46-G34)<0.01,"✅","❌") -> ✅ | E47: =IF(ABS(E46-G35)<0.01,"✅","❌") -> ✅ | F47: =IF(ABS(F46-G36)<0.01,"✅","❌") -> ✅
A49: RISK ADJUSTMENT
...

Sheet P&L (v3a)
A1: INCOME STATEMENT (P&L)
A2: IFRS 17 — Experience Variance (Option A)
C4: 46022 | D4: 46387 | E4: 46752
A5: INSURANCE REVENUE
A6: BEL release — expected claims | C6: ='Assumptions (v3a)'!D12 -> 200 | D6: ='Assumptions (v3a)'!E12 -> 200 | E6: ='Assumptions (v3a)'!F12 -> 200
A7: BEL release — expected expenses | C7: ='Assumptions (v3a)'!D13 -> 50 | D7: ='Assumptions (v3a)'!E13 -> 50 | E7: ='Assumptions (v3a)'!F13 -> 50
A8: Risk Adjustment release | C8: ='Assumptions (v3a)'!C51 -> 30 | D8: ='Assumptions (v3a)'!C51 -> 30 | E8: ='Assumptions (v3a)'!C51 -> 30
A9: CSM release (earned profit) | C9: =-'Assumptions (v3a)'!D64 -> 72.668144 | D9: =-'Assumptions (v3a)'!E64 -> 74.848188 | E9: =-'Assumptions (v3a)'!F64 -> 77.093634
A11: Total Insurance Revenue | C11: =SUM(C6:C9) -> 352.66814 | D11: =SUM(D6:D9) -> 354.84819 | E11: =SUM(E6:E9) -> 357.09363
A13: INSURANCE SERVICE EXPENSE
A14: Actual claims incurred | C14: ='Assumptions (v3a)'!D18 -> 250 | D14: ='Assumptions (v3a)'!E18 -> 250 | E14: ='Assumptions (v3a)'!F18 -> 250
A15: Actual expenses incurred | C15: ='Assumptions (v3a)'!D19 -> 50 | D15: ='Assumptions (v3a)'!E19 -> 50 | E15: ='Assumptions (v3a)'!F19 -> 50
A17: Total Insurance Service Expense | C17: =-(C14+C15) -> -300 | D17: =-(D14+D15) -> -300 | E17: =-(E14+E15) -> -300
A19: INSURANCE SERVICE RESULT | C19: =C11+C17 -> 52.668144 | D19: =D11+D17 -> 54.848188 | E19: =E11+E17 -> 57.093634
A21: INSURANCE FINANCE INCOME / (EXPENSE)
A22: Accretion of BEL (discount unwind) | C22: =-'Assumptions (v3a)'!D44 -> -27.75091 | D22: =-'Assumptions (v3a)'!E44 -> -16.622325 | E22: =-'Assumptions (v3a)'!F44 -> -7.2815534
A23: Effect of discount rate changes | C23: =-'Assumptions (v3a)'!D45 -> 0 | D23: =-'Assumptions (v3a)'!E45 -> 0 | E23: =-'Assumptions (v3a)'!F45 -> 0
A24: Accretion of CSM | C24: =-'Assumptions (v3a)'!D62 -> -6.3496437 | D24: =-'Assumptions (v3a)'!E62 -> -4.3600886 | E24: =-'Assumptions (v3a)'!F62 -> -2.2454457
A25: Total Insurance Finance Income / (Expense) | C25: =SUM(C22:C24) -> -34.100554 | D25: =SUM(D22:D24) -> -20.982414 | E25: =SUM(E22:E24) -> -9.5269991
A27: NET INCOME | C27: =C19+C25 -> 18.56759 | D27: =D19+D25 -> 33.865775 | E27: =E19+E25 -> 47.566635
A29: Cumulative Profit | C29: =C27 -> 18.56759 | D29: =C29+D27 -> 52.433365 | E29: =D29+E27 -> 100
A31: Cash outflows (for BS link)
A32: Total cash paid out (claims + expenses) | C32: ='Assumptions (v3a)'!D20 -> 300 | D32: ='Assumptions (v3a)'!E20 -> 300 | E32: ='Assumptions (v3a)'!F20 -> 300

Sheet Balance Sheet (v3a)
A1: BALANCE SHEET
A2: IFRS 17 — Experience Variance (Option A)
B4: 45658 | C4: 46022 | D4: 46387 | E4: 46752
A5: ASSETS
A6: Cash & Investments | B6: ='Assumptions (v3a)'!C9 -> 1000 | C6: =B6-'P&L (v3a)'!C32 -> 700 | D6: =C6-'P&L (v3a)'!D32 -> 400 | E6: =D6-'P&L (v3a)'!E32 -> 100
A7: Total Assets | B7: =B6 -> 1000 | C7: =C6 -> 700 | D7: =D6 -> 400 | E7: =E6 -> 100
A9: LIABILITIES
A10: Insurance Contract Liability:
A11: BEL (Best Estimate Liability) | B11: ='Assumptions (v3a)'!G33 -> 698.34521 | C11: ='Assumptions (v3a)'!G34 -> 476.09612 | D11: ='Assumptions (v3a)'!G35 -> 242.71845 | E11: ='Assumptions (v3a)'!G36 -> 0
A12: Risk Adjustment | B12: ='Assumptions (v3a)'!C55 -> 90 | C12: =B12-'P&L (v3a)'!C8 -> 60 | D12: =C12-'P&L (v3a)'!D8 -> 30 | E12: =D12-'P&L (v3a)'!E8 -> 0
A13: Fulfilment Cash Flows (BEL + RA) | B13: =B11+B12 -> 788.34521 | C13: =C11+C12 -> 536.09612 | D13: =D11+D12 -> 272.71845 | E13: =E11+E12 -> 0
A14: Contractual Service Margin (CSM) | B14: ='Assumptions (v3a)'!C57 -> 211.65479 | C14: ='Assumptions (v3a)'!D65 -> 145.33629 | D14: ='Assumptions (v3a)'!E65 -> 74.848188 | E14: ='Assumptions (v3a)'!F65 -> 0
A15: Total Insurance Liability | B15: =B13+B14 -> 1000 | C15: =C13+C14 -> 681.43241 | D15: =D13+D14 -> 347.56664 | E15: =E13+E14 -> 0
A16: Total Liabilities | B16: =B15 -> 1000 | C16: =C15 -> 681.43241 | D16: =D15 -> 347.56664 | E16: =E15 -> 0
A18: EQUITY
A19: Retained Earnings | B19: 0 | C19: =B19+'P&L (v3a)'!C27 -> 18.56759 | D19: =C19+'P&L (v3a)'!D27 -> 52.433365 | E19: =D19+'P&L (v3a)'!E27 -> 100
A20: Total Equity | B20: =B19 -> 0 | C20: =C19 -> 18.56759 | D20: =D19 -> 52.433365 | E20: =E19 -> 100
A22: CHECK: Assets = Liabilities + Equity | B22: =IF(ABS(B7-B16-B20)<0.01,"✅ Balanced","❌ "&TEXT(B7-B16-B20,"#,##0.00")) -> ✅ Balanced | C22: =IF(ABS(C7-C16-C20)<0.01,"✅ Balanced","❌ "&TEXT(C7-C16-C20,"#,##0.00")) -> ✅ Balanced | D22: =IF(ABS(D7-D16-D20)<0.01,"✅ Balanced","❌ "&TEXT(D7-D16-D20,"#,##0.00")) -> ✅ Balanced | E22: =IF(ABS(E7-E16-E20)<0.01,"✅ Balanced","❌ "&TEXT(E7-E16-E20,"#,##0.00")) -> ✅ Balanced

Sheet Cash Flow (v3a)
A1: CASH FLOW RECONCILIATION
A2: Ties Balance Sheet cash movement to P&L and liability changes
C4: 46022 | D4: 46387 | E4: 46752
A6: Opening Cash | C6: ='Balance Sheet (v3a)'!B6 -> 1000 | D6: ='Balance Sheet (v3a)'!C6 -> 700 | E6: ='Balance Sheet (v3a)'!D6 -> 400
A8: Cash outflows:
A9: Actual claims paid | C9: =-'Assumptions (v3a)'!D18 -> -250 | D9: =-'Assumptions (v3a)'!E18 -> -250 | E9: =-'Assumptions (v3a)'!F18 -> -250
A10: Actual expenses paid | C10: =-'Assumptions (v3a)'!D19 -> -50 | D10: =-'Assumptions (v3a)'!E19 -> -50 | E10: =-'Assumptions (v3a)'!F19 -> -50
A11: Total Cash Outflows | C11: =SUM(C9:C10) -> -300 | D11: =SUM(D9:D10) -> -300 | E11: =SUM(E9:E10) -> -300
A13: Closing Cash | C13: =C6+C11 -> 700 | D13: =D6+D11 -> 400 | E13: =E6+E11 -> 100
A15: CHECK: Ties to Balance Sheet | C15: =IF(ABS(C13-'Balance Sheet (v3a)'!C6)<0.01,"✅ Ties","❌ "&TEXT(C13-'Balance Sheet (v3a)'!C6,"#,##0.00")) -> ✅ Ties | D15: =IF(ABS(D13-'Balance Sheet (v3a)'!D6)<0.01,"✅ Ties","❌ "&TEXT(D13-'Balance Sheet (v3a)'!D6,"#,##0.00")) -> ✅ Ties | E15: =IF(ABS(E13-'Balance Sheet (v3a)'!E6)<0.01,"✅ Ties","❌ "&TEXT(E13-'Balance Sheet (v3a)'!E6,"#,##0.00")) -> ✅ Ties
A18: LIABILITY ROLLFORWARD
A19: Shows how the insurance liability changes each year
C20: Year 1 | D20: Year 2 | E20: Year 3
A22: Opening Liability | C22: ='Balance Sheet (v3a)'!B15 -> 1000 | D22: ='Balance Sheet (v3a)'!C15 -> 681.43241 | E22: ='Balance Sheet (v3a)'!D15 -> 347.56664
A24: Releases to P&L (reduce liability):
A25: BEL release (expected costs) | C25: =-('P&L (v3a)'!C6+'P&L (v3a)'!C7) -> -250 | D25: =-('P&L (v3a)'!D6+'P&L (v3a)'!D7) -> -250 | E25: =-('P&L (v3a)'!E6+'P&L (v3a)'!E7) -> -250
A26: Risk Adjustment release | C26: =-'P&L (v3a)'!C8 -> -30 | D26: =-'P&L (v3a)'!D8 -> -30 | E26: =-'P&L (v3a)'!E8 -> -30
A27: CSM release | C27: =-'P&L (v3a)'!C9 -> -72.668144 | D27: =-'P&L (v3a)'!D9 -> -74.848188 | E27: =-'P&L (v3a)'!E9 -> -77.093634
A28: Total Releases | C28: =SUM(C25:C27) -> -352.66814 | D28: =SUM(D25:D27) -> -354.84819 | E28: =SUM(E25:E27) -> -357.09363
A30: Insurance Finance (increase liability):
A31: BEL accretion (discount unwind) | C31: ='Assumptions (v3a)'!D44 -> 27.75091 | D31: ='Assumptions (v3a)'!E44 -> 16.622325 | E31: ='Assumptions (v3a)'!F44 -> 7.2815534
A32: Effect of discount rate changes | C32: ='Assumptions (v3a)'!D45 -> 0 | D32: ='Assumptions (v3a)'!E45 -> 0 | E32: ='Assumptions (v3a)'!F45 -> 0
A33: CSM accretion | C33: ='Assumptions (v3a)'!D62 -> 6.3496437 | D33: ='Assumptions (v3a)'!E62 -> 4.3600886 | E33: ='Assumptions (v3a)'!F62 -> 2.2454457
A34: Total Insurance Finance | C34: =SUM(C31:C33) -> 34.100554 | D34: =SUM(D31:D33) -> 20.982414 | E34: =SUM(E31:E33) -> 9.5269991
A36: Closing Liability | C36: =C22+C28+C34 -> 681.43241 | D36: =D22+D28+D34 -> 347.56664 | E36: =E22+E28+E34 -> 2.1316282e-14
A38: CHECK: Ties to Balance Sheet | C38: =IF(ABS(C36-'Balance Sheet (v3a)'!C15)<0.01,"✅ Ties","❌ "&TEXT(C36-'Balance Sheet (v3a)'!C15,"#,##0.00")) -> ✅ Ties | D38: =IF(ABS(D36-'Balance Sheet (v3a)'!D15)<0.01,"✅ Ties","❌ "&TEXT(D36-'Balance Sheet (v3a)'!D15,"#,##0.00")) -> ✅ Ties | E38: =IF(ABS(E36-'Balance Sheet (v3a)'!E15)<0.01,"✅ Ties","❌ "&TEXT(E36-'Balance Sheet (v3a)'!E15,"#,##0.00")) -> ✅ Ties

Sheet Re-estimation (Option B) →

Sheet Assumptions (v3b)
A1: IFRS 17 — Re-estimation (Option B)
A2: Simplifications:
A3: • Actual claims exceed expected; insurer re-estimates future claims at end of Year 1
A4: • CSM absorbs the BEL increase from re-estimation (no onerous contract)
A5: • Assets consist solely of cash; all finance through P&L (no OCI)
A7: CONTRACT DETAILS
A8: Coverage period (years) | C8: 3
A9: Premiums collected (upfront) | C9: 1000
A11: ORIGINAL EXPECTED CASH FLOWS (at inception) | C11: Total | D11: 46022 | E11: 46387 | F11: 46752
A12: Expected claims | C12: 600 | D12: =C12/C8 -> 200 | E12: =C12/C8 -> 200 | F12: =C12/C8 -> 200
A13: Expected expenses | C13: 150 | D13: =C13/C8 -> 50 | E13: =C13/C8 -> 50 | F13: =C13/C8 -> 50
A14: Total expected undiscounted outflows | C14: =C12+C13 -> 750 | D14: =D12+D13 -> 250 | E14: =E12+E13 -> 250 | F14: =F12+F13 -> 250
A15: Risk Adjustment (total, undiscounted) | C15: 90
A17: REVISED EXPECTED CASH FLOWS (at end of Year 1) | E17: 46387 | F17: 46752
A18: Revised expected claims | E18: 250 | F18: 250
A19: Expected expenses (unchanged) | E19: =E13 -> 50 | F19: =F13 -> 50
A20: Total revised outflows | E20: =E18+E19 -> 300 | F20: =F18+F19 -> 300
A22: ACTUAL CASH FLOWS | D22: 46022 | E22: 46387 | F22: 46752
A23: Actual claims | D23: 250 | E23: 250 | F23: 250
A24: Actual expenses | D24: =D13 -> 50 | E24: =E13 -> 50 | F24: =F13 -> 50
A25: Total actual outflows | D25: =D23+D24 -> 300 | E25: =E23+E24 -> 300 | F25: =F23+F24 -> 300
A27: YIELD CURVE (Spot Rates) | D27: 1Y Spot | E27: 2Y Spot | F27: 3Y Spot
A28: Curve at Inception (t=0) | D28: 0.03 | E28: 0.035 | F28: 0.04
A29: Curve at End Year 1 (t=1) | D29: 0.03 | E29: 0.035
A30: Curve at End Year 2 (t=2) | D30: 0.03
A32: DISCOUNT FACTORS | D32: DF 1Y | E32: DF 2Y | F32: DF 3Y
A33: DFs at Inception (t=0) | D33: =1/(1+D28)^1 -> 0.97087379 | E33: =1/(1+E28)^2 -> 0.9335107 | F33: =1/(1+F28)^3 -> 0.88899636
A34: DFs at End Year 1 (t=1) | D34: =1/(1+D29)^1 -> 0.97087379 | E34: =1/(1+E29)^2 -> 0.9335107
A35: DFs at End Year 2 (t=2) | D35: =1/(1+D30)^1 -> 0.97087379
A37: BEL (DISCOUNTED) AT EACH DATE | D37: PV of Y1 CFs | E37: PV of Y2 CFs | F37: PV of Y3 CFs | G37: BEL Total
A38: BEL at Inception (t=0) — original estimates | D38: =D14*D33 -> 242.71845 | E38: =E14*E33 -> 233.37768 | F38: =F14*F33 -> 222.24909 | G38: =SUM(D38:F38) -> 698.34521
A39: BEL at End Y1 (t=1) — original estimates, NEW curve | E39: =E14*D34 -> 242.71845 | F39: =F14*E34 -> 233.37768 | G39: =SUM(E39:F39) -> 476.09612
A40: BEL at End Y1 (t=1) — REVISED estimates, NEW curve | E40: =E20*D34 -> 291.26214 | F40: =F20*E34 -> 280.05321 | G40: =SUM(E40:F40) -> 571.31535
A41: BEL at End Y2 (t=2) — revised estimates, NEW curve | F41: =F20*D35 -> 291.26214 | G41: =F41 -> 291.26214
A42: BEL at End Y3 (t=3) | G42: 0
A44: BEL at End Y1 — using OLD curve (for accretion) | E44: =E14*D33 -> 242.71845 | F44: =F14*E33 -> 233.37768 | G44: =SUM(E44:F44) -> 476.09612
A45: BEL at End Y2 — using OLD curve (for accretion) | F45: =F20*D33 -> 291.26214 | G45: =F45 -> 291.26214
A47: BEL ROLLFORWARD COMPONENTS | D47: 46022 | E47: 46387 | F47: 46752
A48: Opening BEL | D48: =G38 -> 698.34521 | E48: =G40 -> 571.31535 | F48: =G41 -> 291.26214
A49: Less: BEL release (expected outflows) | D49: =-D14 -> -250 | E49: =-E20 -> -300 | F49: =-F20 -> -300
...

Sheet P&L (v3b)
A1: INCOME STATEMENT (P&L)
A2: IFRS 17 — Re-estimation (Option B)
C4: 46022 | D4: 46387 | E4: 46752
A5: INSURANCE REVENUE
A6: BEL release — expected claims | C6: ='Assumptions (v3b)'!D12 -> 200 | D6: ='Assumptions (v3b)'!E18 -> 250 | E6: ='Assumptions (v3b)'!F18 -> 250
A7: BEL release — expected expenses | C7: ='Assumptions (v3b)'!D13 -> 50 | D7: ='Assumptions (v3b)'!E19 -> 50 | E7: ='Assumptions (v3b)'!F19 -> 50
A8: Risk Adjustment release | C8: ='Assumptions (v3b)'!C58 -> 30 | D8: ='Assumptions (v3b)'!C58 -> 30 | E8: ='Assumptions (v3b)'!C58 -> 30
A9: CSM release (earned profit) | C9: =-'Assumptions (v3b)'!D71 -> 40.928403 | D9: =-'Assumptions (v3b)'!E71 -> 42.156255 | E9: =-'Assumptions (v3b)'!F71 -> 43.420942
A11: Total Insurance Revenue | C11: =SUM(C6:C9) -> 320.9284 | D11: =SUM(D6:D9) -> 372.15625 | E11: =SUM(E6:E9) -> 373.42094
A13: INSURANCE SERVICE EXPENSE
A14: Actual claims incurred | C14: ='Assumptions (v3b)'!D23 -> 250 | D14: ='Assumptions (v3b)'!E23 -> 250 | E14: ='Assumptions (v3b)'!F23 -> 250
A15: Actual expenses incurred | C15: ='Assumptions (v3b)'!D24 -> 50 | D15: ='Assumptions (v3b)'!E24 -> 50 | E15: ='Assumptions (v3b)'!F24 -> 50
A17: Total Insurance Service Expense | C17: =-(C14+C15) -> -300 | D17: =-(D14+D15) -> -300 | E17: =-(E14+E15) -> -300
A19: INSURANCE SERVICE RESULT | C19: =C11+C17 -> 20.928403 | D19: =D11+D17 -> 72.156255 | E19: =E11+E17 -> 73.420942
A21: INSURANCE FINANCE INCOME / (EXPENSE)
A22: Accretion of BEL (discount unwind) | C22: =-'Assumptions (v3b)'!D50 -> -27.75091 | D22: =-'Assumptions (v3b)'!E50 -> -19.94679 | E22: =-'Assumptions (v3b)'!F50 -> -8.7378641
A23: Effect of discount rate changes | C23: =-'Assumptions (v3b)'!D51 -> 0 | D23: =-'Assumptions (v3b)'!E51 -> 0 | E23: =-'Assumptions (v3b)'!F51 -> 0
A24: Accretion of CSM | C24: =-'Assumptions (v3b)'!D69 -> -6.3496437 | D24: =-'Assumptions (v3b)'!E69 -> -2.4557042 | E24: =-'Assumptions (v3b)'!F69 -> -1.2646876
A25: Total Insurance Finance Income / (Expense) | C25: =SUM(C22:C24) -> -34.100554 | D25: =SUM(D22:D24) -> -22.402494 | E25: =SUM(E22:E24) -> -10.002552
A27: NET INCOME | C27: =C19+C25 -> -13.172151 | D27: =D19+D25 -> 49.753761 | E27: =E19+E25 -> 63.418391
A29: Cumulative Profit | C29: =C27 -> -13.172151 | D29: =C29+D27 -> 36.581609 | E29: =D29+E27 -> 100
A31: Cash outflows (for BS link)
A32: Total cash paid out (claims + expenses) | C32: ='Assumptions (v3b)'!D25 -> 300 | D32: ='Assumptions (v3b)'!E25 -> 300 | E32: ='Assumptions (v3b)'!F25 -> 300

Sheet Balance Sheet (v3b)
A1: BALANCE SHEET
A2: IFRS 17 — Re-estimation (Option B)
B4: 45658 | C4: 46022 | D4: 46387 | E4: 46752
A5: ASSETS
A6: Cash & Investments | B6: ='Assumptions (v3b)'!C9 -> 1000 | C6: =B6-'P&L (v3b)'!C32 -> 700 | D6: =C6-'P&L (v3b)'!D32 -> 400 | E6: =D6-'P&L (v3b)'!E32 -> 100
A7: Total Assets | B7: =B6 -> 1000 | C7: =C6 -> 700 | D7: =D6 -> 400 | E7: =E6 -> 100
A9: LIABILITIES
A10: Insurance Contract Liability:
A11: BEL (Best Estimate Liability) | B11: ='Assumptions (v3b)'!G38 -> 698.34521 | C11: ='Assumptions (v3b)'!G40 -> 571.31535 | D11: ='Assumptions (v3b)'!G41 -> 291.26214 | E11: ='Assumptions (v3b)'!G42 -> 0
A12: Risk Adjustment | B12: ='Assumptions (v3b)'!C62 -> 90 | C12: =B12-'P&L (v3b)'!C8 -> 60 | D12: =C12-'P&L (v3b)'!D8 -> 30 | E12: =D12-'P&L (v3b)'!E8 -> 0
A13: Fulfilment Cash Flows (BEL + RA) | B13: =B11+B12 -> 788.34521 | C13: =C11+C12 -> 631.31535 | D13: =D11+D12 -> 321.26214 | E13: =E11+E12 -> 0
A14: Contractual Service Margin (CSM) | B14: ='Assumptions (v3b)'!C64 -> 211.65479 | C14: ='Assumptions (v3b)'!D73 -> 81.856805 | D14: ='Assumptions (v3b)'!E73 -> 42.156255 | E14: ='Assumptions (v3b)'!F73 -> 0
A15: Total Insurance Liability | B15: =B13+B14 -> 1000 | C15: =C13+C14 -> 713.17215 | D15: =D13+D14 -> 363.41839 | E15: =E13+E14 -> 0
A16: Total Liabilities | B16: =B15 -> 1000 | C16: =C15 -> 713.17215 | D16: =D15 -> 363.41839 | E16: =E15 -> 0
A18: EQUITY
A19: Retained Earnings | B19: 0 | C19: =B19+'P&L (v3b)'!C27 -> -13.172151 | D19: =C19+'P&L (v3b)'!D27 -> 36.581609 | E19: =D19+'P&L (v3b)'!E27 -> 100
A20: Total Equity | B20: =B19 -> 0 | C20: =C19 -> -13.172151 | D20: =D19 -> 36.581609 | E20: =E19 -> 100
A22: CHECK: Assets = Liabilities + Equity | B22: =IF(ABS(B7-B16-B20)<0.01,"✅ Balanced","❌ "&TEXT(B7-B16-B20,"#,##0.00")) -> ✅ Balanced | C22: =IF(ABS(C7-C16-C20)<0.01,"✅ Balanced","❌ "&TEXT(C7-C16-C20,"#,##0.00")) -> ✅ Balanced | D22: =IF(ABS(D7-D16-D20)<0.01,"✅ Balanced","❌ "&TEXT(D7-D16-D20,"#,##0.00")) -> ✅ Balanced | E22: =IF(ABS(E7-E16-E20)<0.01,"✅ Balanced","❌ "&TEXT(E7-E16-E20,"#,##0.00")) -> ✅ Balanced

Sheet Cash Flow (v3b)
A1: CASH FLOW RECONCILIATION
A2: Ties Balance Sheet cash movement to P&L and liability changes
C4: 46022 | D4: 46387 | E4: 46752
A6: Opening Cash | C6: ='Balance Sheet (v3b)'!B6 -> 1000 | D6: ='Balance Sheet (v3b)'!C6 -> 700 | E6: ='Balance Sheet (v3b)'!D6 -> 400
A8: Cash outflows:
A9: Actual claims paid | C9: =-'Assumptions (v3b)'!D23 -> -250 | D9: =-'Assumptions (v3b)'!E23 -> -250 | E9: =-'Assumptions (v3b)'!F23 -> -250
A10: Actual expenses paid | C10: =-'Assumptions (v3b)'!D24 -> -50 | D10: =-'Assumptions (v3b)'!E24 -> -50 | E10: =-'Assumptions (v3b)'!F24 -> -50
A11: Total Cash Outflows | C11: =SUM(C9:C10) -> -300 | D11: =SUM(D9:D10) -> -300 | E11: =SUM(E9:E10) -> -300
A13: Closing Cash | C13: =C6+C11 -> 700 | D13: =D6+D11 -> 400 | E13: =E6+E11 -> 100
A15: CHECK: Ties to Balance Sheet | C15: =IF(ABS(C13-'Balance Sheet (v3b)'!C6)<0.01,"✅ Ties","❌ "&TEXT(C13-'Balance Sheet (v3b)'!C6,"#,##0.00")) -> ✅ Ties | D15: =IF(ABS(D13-'Balance Sheet (v3b)'!D6)<0.01,"✅ Ties","❌ "&TEXT(D13-'Balance Sheet (v3b)'!D6,"#,##0.00")) -> ✅ Ties | E15: =IF(ABS(E13-'Balance Sheet (v3b)'!E6)<0.01,"✅ Ties","❌ "&TEXT(E13-'Balance Sheet (v3b)'!E6,"#,##0.00")) -> ✅ Ties
A18: LIABILITY ROLLFORWARD
A19: Shows how the insurance liability changes each year
C20: Year 1 | D20: Year 2 | E20: Year 3
A22: Opening Liability | C22: ='Balance Sheet (v3b)'!B15 -> 1000 | D22: ='Balance Sheet (v3b)'!C15 -> 713.17215 | E22: ='Balance Sheet (v3b)'!D15 -> 363.41839
A24: Releases to P&L (reduce liability):
A25: BEL release (expected costs) | C25: =-('P&L (v3b)'!C6+'P&L (v3b)'!C7) -> -250 | D25: =-('P&L (v3b)'!D6+'P&L (v3b)'!D7) -> -300 | E25: =-('P&L (v3b)'!E6+'P&L (v3b)'!E7) -> -300
A26: Risk Adjustment release | C26: =-'P&L (v3b)'!C8 -> -30 | D26: =-'P&L (v3b)'!D8 -> -30 | E26: =-'P&L (v3b)'!E8 -> -30
A27: CSM release | C27: =-'P&L (v3b)'!C9 -> -40.928403 | D27: =-'P&L (v3b)'!D9 -> -42.156255 | E27: =-'P&L (v3b)'!E9 -> -43.420942
A28: Total Releases | C28: =SUM(C25:C27) -> -320.9284 | D28: =SUM(D25:D27) -> -372.15625 | E28: =SUM(E25:E27) -> -373.42094
A30: Insurance Finance (increase liability):
A31: BEL accretion | C31: ='Assumptions (v3b)'!D50 -> 27.75091 | D31: ='Assumptions (v3b)'!E50 -> 19.94679 | E31: ='Assumptions (v3b)'!F50 -> 8.7378641
A32: Effect of discount rate changes | C32: ='Assumptions (v3b)'!D51 -> 0 | D32: ='Assumptions (v3b)'!E51 -> 0 | E32: ='Assumptions (v3b)'!F51 -> 0
A33: CSM accretion | C33: ='Assumptions (v3b)'!D69 -> 6.3496437 | D33: ='Assumptions (v3b)'!E69 -> 2.4557042 | E33: ='Assumptions (v3b)'!F69 -> 1.2646876
A34: Total Insurance Finance | C34: =SUM(C31:C33) -> 34.100554 | D34: =SUM(D31:D33) -> 22.402494 | E34: =SUM(E31:E33) -> 10.002552
A36: Changes in estimates (BEL ↑, CSM ↓) | C36: 0 | D36: 0 | E36: 0
A38: Closing Liability | C38: =C22+C28+C34+C36 -> 713.17215 | D38: =D22+D28+D34+D36 -> 363.41839 | E38: =E22+E28+E34+E36 -> 2.6645353e-14
A40: CHECK: Ties to Balance Sheet | C40: =IF(ABS(C38-'Balance Sheet (v3b)'!C15)<0.01,"✅ Ties","❌ "&TEXT(C38-'Balance Sheet (v3b)'!C15,"#,##0.00")) -> ✅ Ties | D40: =IF(ABS(D38-'Balance Sheet (v3b)'!D15)<0.01,"✅ Ties","❌ "&TEXT(D38-'Balance Sheet (v3b)'!D15,"#,##0.00")) -> ✅ Ties | E40: =IF(ABS(E38-'Balance Sheet (v3b)'!E15)<0.01,"✅ Ties","❌ "&TEXT(E38-'Balance Sheet (v3b)'!E15,"#,##0.00")) -> ✅ Ties

Sheet Onerous Contract →
A1: v4 — Onerous Contract (Loss Component)
A3: Actual claims far exceed expectations → CSM exhausted → loss recognised immediately

Sheet Assumptions (v4)
A1: IFRS 17 — Onerous Contract (Loss Component)
A2: Simplifications:
A3: • Actual claims far exceed expected; insurer re-estimates → CSM is exhausted → Loss Component created
A4: • Loss recognised immediately in P&L; Loss Component released over remaining coverage period
A5: • Assets consist solely of cash; all finance through P&L (no OCI)
A7: CONTRACT DETAILS
A8: Coverage period (years) | C8: 3
A9: Premiums collected (upfront) | C9: 1000
A11: ORIGINAL EXPECTED CASH FLOWS (at inception) | C11: Total | D11: 46022 | E11: 46387 | F11: 46752
A12: Expected claims | C12: 600 | D12: =C12/C8 -> 200 | E12: =C12/C8 -> 200 | F12: =C12/C8 -> 200
A13: Expected expenses | C13: 150 | D13: =C13/C8 -> 50 | E13: =C13/C8 -> 50 | F13: =C13/C8 -> 50
A14: Total expected undiscounted outflows | C14: =C12+C13 -> 750 | D14: =D12+D13 -> 250 | E14: =E12+E13 -> 250 | F14: =F12+F13 -> 250
A15: Risk Adjustment (total, undiscounted) | C15: 90
A17: REVISED EXPECTED CASH FLOWS (at end of Year 1) | E17: 46387 | F17: 46752
A18: Revised expected claims | E18: 400 | F18: 400
A19: Expected expenses (unchanged) | E19: =E13 -> 50 | F19: =F13 -> 50
A20: Total revised outflows | E20: =E18+E19 -> 450 | F20: =F18+F19 -> 450
A22: ACTUAL CASH FLOWS | D22: 46022 | E22: 46387 | F22: 46752
A23: Actual claims | D23: 400 | E23: 400 | F23: 400
A24: Actual expenses | D24: =D13 -> 50 | E24: =E13 -> 50 | F24: =F13 -> 50
A25: Total actual outflows | D25: =D23+D24 -> 450 | E25: =E23+E24 -> 450 | F25: =F23+F24 -> 450
A27: YIELD CURVE (Spot Rates) | D27: 1Y Spot | E27: 2Y Spot | F27: 3Y Spot
A28: Curve at Inception (t=0) | D28: 0.03 | E28: 0.035 | F28: 0.04
A29: Curve at End Year 1 (t=1) | D29: 0.03 | E29: 0.035
A30: Curve at End Year 2 (t=2) | D30: 0.03
A32: DISCOUNT FACTORS | D32: DF 1Y | E32: DF 2Y | F32: DF 3Y
A33: DFs at Inception (t=0) | D33: =1/(1+D28)^1 -> 0.97087379 | E33: =1/(1+E28)^2 -> 0.9335107 | F33: =1/(1+F28)^3 -> 0.88899636
A34: DFs at End Year 1 (t=1) | D34: =1/(1+D29)^1 -> 0.97087379 | E34: =1/(1+E29)^2 -> 0.9335107
A35: DFs at End Year 2 (t=2) | D35: =1/(1+D30)^1 -> 0.97087379
A37: BEL (DISCOUNTED) AT EACH DATE | D37: PV of Y1 CFs | E37: PV of Y2 CFs | F37: PV of Y3 CFs | G37: BEL Total
A38: BEL at Inception (t=0) — original estimates | D38: =D14*D33 -> 242.71845 | E38: =E14*E33 -> 233.37768 | F38: =F14*F33 -> 222.24909 | G38: =SUM(D38:F38) -> 698.34521
A39: BEL at End Y1 (t=1) — original estimates, NEW curve | E39: =E14*D34 -> 242.71845 | F39: =F14*E34 -> 233.37768 | G39: =SUM(E39:F39) -> 476.09612
A40: BEL at End Y1 (t=1) — REVISED estimates, NEW curve | E40: =E20*D34 -> 436.8932 | F40: =F20*E34 -> 420.07982 | G40: =SUM(E40:F40) -> 856.97302
A41: BEL at End Y2 (t=2) — revised estimates, NEW curve | F41: =F20*D35 -> 436.8932 | G41: =F41 -> 436.8932
A42: BEL at End Y3 (t=3) | G42: 0
A44: BEL at End Y1 — using OLD curve (for accretion) | E44: =E14*D33 -> 242.71845 | F44: =F14*E33 -> 233.37768 | G44: =SUM(E44:F44) -> 476.09612
A45: BEL at End Y2 — using OLD curve (for accretion) | F45: =F20*D33 -> 436.8932 | G45: =F45 -> 436.8932
A47: BEL ROLLFORWARD COMPONENTS | D47: 46022 | E47: 46387 | F47: 46752
A48: Opening BEL | D48: =G38 -> 698.34521 | E48: =G40 -> 856.97302 | F48: =G41 -> 436.8932
A49: Less: BEL release (expected outflows) | D49: =-D14 -> -250 | E49: =-E20 -> -450 | F49: =-F20 -> -450
...

Sheet P&L (v4)
A1: INCOME STATEMENT (P&L)
A2: IFRS 17 — Onerous Contract (Loss Component)
C4: 46022 | D4: 46387 | E4: 46752
A5: INSURANCE REVENUE
A6: BEL release — expected claims | C6: ='Assumptions (v4)'!D12 -> 200 | D6: ='Assumptions (v4)'!E18 -> 400 | E6: ='Assumptions (v4)'!F18 -> 400
A7: BEL release — expected expenses | C7: ='Assumptions (v4)'!D13 -> 50 | D7: ='Assumptions (v4)'!E19 -> 50 | E7: ='Assumptions (v4)'!F19 -> 50
A8: Risk Adjustment release | C8: ='Assumptions (v4)'!C58 -> 30 | D8: ='Assumptions (v4)'!C58 -> 30 | E8: ='Assumptions (v4)'!C58 -> 30
A9: CSM release (earned profit) | C9: =-'Assumptions (v4)'!D73 -> 0 | D9: =-'Assumptions (v4)'!E73 -> 0 | E9: =-'Assumptions (v4)'!F73 -> 0
A11: Total Insurance Revenue | C11: =SUM(C6:C9) -> 280 | D11: =SUM(D6:D9) -> 480 | E11: =SUM(E6:E9) -> 480
A13: INSURANCE SERVICE EXPENSE
A14: Actual claims incurred | C14: ='Assumptions (v4)'!D23 -> 400 | D14: ='Assumptions (v4)'!E23 -> 400 | E14: ='Assumptions (v4)'!F23 -> 400
A15: Actual expenses incurred | C15: ='Assumptions (v4)'!D24 -> 50 | D15: ='Assumptions (v4)'!E24 -> 50 | E15: ='Assumptions (v4)'!F24 -> 50
A17: Subtotal | C17: =-(C14+C15) -> -450 | D17: =-(D14+D15) -> -450 | E17: =-(E14+E15) -> -450
A18: Losses on onerous contracts | C18: ='Assumptions (v4)'!D72 -> -162.87247 | D18: ='Assumptions (v4)'!E72 -> 0 | E18: ='Assumptions (v4)'!F72 -> 0
A20: Total Insurance Service Expense | C20: =C17+C18 -> -612.87247 | D20: =D17+D18 -> -450 | E20: =E17+E18 -> -450
A22: INSURANCE SERVICE RESULT | C22: =C11+C20 -> -332.87247 | D22: =D11+D20 -> 30 | E22: =E11+E20 -> 30
A23: INSURANCE FINANCE INCOME / (EXPENSE)
A24: Accretion of BEL (discount unwind) | C24: =-'Assumptions (v4)'!D50 -> -27.75091 | D24: =-'Assumptions (v4)'!E50 -> -29.920185 | E24: =-'Assumptions (v4)'!F50 -> -13.106796
A25: Effect of discount rate changes | C25: =-'Assumptions (v4)'!D51 -> 0 | D25: =-'Assumptions (v4)'!E51 -> 0 | E25: =-'Assumptions (v4)'!F51 -> 0
A26: Accretion of CSM | C26: =-'Assumptions (v4)'!D69 -> -6.3496437 | D26: =-'Assumptions (v4)'!E69 -> 0 | E26: =-'Assumptions (v4)'!F69 -> 0
A27: Total Insurance Finance Income / (Expense) | C27: =SUM(C24:C26) -> -34.100554 | D27: =SUM(D24:D26) -> -29.920185 | E27: =SUM(E24:E26) -> -13.106796
A29: NET INCOME | C29: =C22+C27 -> -366.97302 | D29: =D22+D27 -> 0.079815165 | E29: =E22+E27 -> 16.893204
A31: Cumulative Profit | C31: =C29 -> -366.97302 | D31: =C31+D29 -> -366.8932 | E31: =D31+E29 -> -350
A33: Cash outflows (for BS link)
A34: Total cash paid out (claims + expenses) | C34: ='Assumptions (v4)'!D25 -> 450 | D34: ='Assumptions (v4)'!E25 -> 450 | E34: ='Assumptions (v4)'!F25 -> 450

Sheet Balance Sheet (v4)
A1: BALANCE SHEET
A2: IFRS 17 — Onerous Contract (Loss Component)
B4: 45658 | C4: 46022 | D4: 46387 | E4: 46752
A5: ASSETS
A6: Cash & Investments | B6: ='Assumptions (v4)'!C9 -> 1000 | C6: =B6-'P&L (v4)'!C34 -> 550 | D6: =C6-'P&L (v4)'!D34 -> 100 | E6: =D6-'P&L (v4)'!E34 -> -350
A7: Total Assets | B7: =B6 -> 1000 | C7: =C6 -> 550 | D7: =D6 -> 100 | E7: =E6 -> -350
C8: =C6 -> 550 | D8: =D6 -> 100 | E8: =E6 -> -350
A9: LIABILITIES
A10: Insurance Contract Liability:
A11: BEL (Best Estimate Liability) | B11: ='Assumptions (v4)'!G38 -> 698.34521 | C11: ='Assumptions (v4)'!G40 -> 856.97302 | D11: ='Assumptions (v4)'!G41 -> 436.8932 | E11: ='Assumptions (v4)'!G42 -> 0
A12: Risk Adjustment | B12: ='Assumptions (v4)'!C62 -> 90 | C12: =B12-'P&L (v4)'!C8 -> 60 | D12: =C12-'P&L (v4)'!D8 -> 30 | E12: =D12-'P&L (v4)'!E8 -> 0
A13: Fulfilment Cash Flows (BEL + RA) | B13: =B11+B12 -> 788.34521 | C13: =C11+C12 -> 916.97302 | D13: =D11+D12 -> 466.8932 | E13: =E11+E12 -> 0
A14: Contractual Service Margin (CSM) | B14: ='Assumptions (v4)'!C64 -> 211.65479 | C14: ='Assumptions (v4)'!D75 -> 0 | D14: ='Assumptions (v4)'!E75 -> 0 | E14: ='Assumptions (v4)'!F75 -> 0
A15: Loss Component (memo — within FCF) | B15: 0 | C15: ='Assumptions (v4)'!D82 -> 162.87247 | D15: ='Assumptions (v4)'!E82 -> 77.347475 | E15: ='Assumptions (v4)'!F82 -> 0
A16: Total Insurance Liability | B16: =B13+B14 -> 1000 | C16: =C13+C14 -> 916.97302 | D16: =D13+D14 -> 466.8932 | E16: =E13+E14 -> 0
A17: Total Liabilities | B17: =B16 -> 1000 | C17: =C16 -> 916.97302 | D17: =D16 -> 466.8932 | E17: =E16 -> 0
A19: EQUITY
A20: Retained Earnings | B20: 0 | C20: =B20+'P&L (v4)'!C29 -> -366.97302 | D20: =C20+'P&L (v4)'!D29 -> -366.8932 | E20: =D20+'P&L (v4)'!E29 -> -350
A21: Total Equity | B21: =B20 -> 0 | C21: =C20 -> -366.97302 | D21: =D20 -> -366.8932 | E21: =E20 -> -350
A23: CHECK: Assets = Liabilities + Equity | B23: =IF(ABS(B7-B17-B21)<0.01,"✅ Balanced","❌ "&TEXT(B7-B17-B21,"#,##0.00")) -> ✅ Balanced | C23: =IF(ABS(C7-C17-C21)<0.01,"✅ Balanced","❌ "&TEXT(C7-C17-C21,"#,##0.00")) -> ✅ Balanced | D23: =IF(ABS(D7-D17-D21)<0.01,"✅ Balanced","❌ "&TEXT(D7-D17-D21,"#,##0.00")) -> ✅ Balanced | E23: =IF(ABS(E7-E17-E21)<0.01,"✅ Balanced","❌ "&TEXT(E7-E17-E21,"#,##0.00")) -> ✅ Balanced

Sheet Cash Flow (v4)
A1: CASH FLOW RECONCILIATION
A2: Ties Balance Sheet cash movement to P&L and liability changes
C4: 46022 | D4: 46387 | E4: 46752
A6: Opening Cash | C6: ='Balance Sheet (v4)'!B6 -> 1000 | D6: ='Balance Sheet (v4)'!C6 -> 550 | E6: ='Balance Sheet (v4)'!D6 -> 100
A8: Cash outflows:
A9: Actual claims paid | C9: =-'Assumptions (v4)'!D23 -> -400 | D9: =-'Assumptions (v4)'!E23 -> -400 | E9: =-'Assumptions (v4)'!F23 -> -400
A10: Actual expenses paid | C10: =-'Assumptions (v4)'!D24 -> -50 | D10: =-'Assumptions (v4)'!E24 -> -50 | E10: =-'Assumptions (v4)'!F24 -> -50
A11: Total Cash Outflows | C11: =SUM(C9:C10) -> -450 | D11: =SUM(D9:D10) -> -450 | E11: =SUM(E9:E10) -> -450
A13: Closing Cash | C13: =C6+C11 -> 550 | D13: =D6+D11 -> 100 | E13: =E6+E11 -> -350
A15: CHECK: Ties to Balance Sheet | C15: =IF(ABS(C13-'Balance Sheet (v4)'!C6)<0.01,"✅ Ties","❌ "&TEXT(C13-'Balance Sheet (v4)'!C6,"#,##0.00")) -> ✅ Ties | D15: =IF(ABS(D13-'Balance Sheet (v4)'!D6)<0.01,"✅ Ties","❌ "&TEXT(D13-'Balance Sheet (v4)'!D6,"#,##0.00")) -> ✅ Ties | E15: =IF(ABS(E13-'Balance Sheet (v4)'!E6)<0.01,"✅ Ties","❌ "&TEXT(E13-'Balance Sheet (v4)'!E6,"#,##0.00")) -> ✅ Ties
A18: LIABILITY ROLLFORWARD
A19: Shows how the insurance liability changes each year
C20: Year 1 | D20: Year 2 | E20: Year 3
A22: Opening Liability | C22: ='Balance Sheet (v4)'!B16 -> 1000 | D22: ='Balance Sheet (v4)'!C16 -> 916.97302 | E22: ='Balance Sheet (v4)'!D16 -> 466.8932
A24: Releases to P&L (reduce liability):
A25: BEL release (expected costs) | C25: =-('P&L (v4)'!C6+'P&L (v4)'!C7) -> -250 | D25: =-('P&L (v4)'!D6+'P&L (v4)'!D7) -> -450 | E25: =-('P&L (v4)'!E6+'P&L (v4)'!E7) -> -450
A26: Risk Adjustment release | C26: =-'P&L (v4)'!C8 -> -30 | D26: =-'P&L (v4)'!D8 -> -30 | E26: =-'P&L (v4)'!E8 -> -30
A27: CSM release | C27: =-'P&L (v4)'!C9 -> 0 | D27: =-'P&L (v4)'!D9 -> 0 | E27: =-'P&L (v4)'!E9 -> 0
A28: Total Releases | C28: =SUM(C25:C27) -> -280 | D28: =SUM(D25:D27) -> -480 | E28: =SUM(E25:E27) -> -480
A30: Insurance Finance (increase liability):
A31: BEL accretion | C31: ='Assumptions (v4)'!D50 -> 27.75091 | D31: ='Assumptions (v4)'!E50 -> 29.920185 | E31: ='Assumptions (v4)'!F50 -> 13.106796
A32: Effect of discount rate changes | C32: ='Assumptions (v4)'!D51 -> 0 | D32: ='Assumptions (v4)'!E51 -> 0 | E32: ='Assumptions (v4)'!F51 -> 0
A33: CSM accretion | C33: ='Assumptions (v4)'!D69 -> 6.3496437 | D33: ='Assumptions (v4)'!E69 -> 0 | E33: ='Assumptions (v4)'!F69 -> 0
