Workbook

Sheet Read me
B2: IFRS 17 FINANCIAL STATEMENTS
B3: A step-by-step model of IFRS 17 accounting mechanics
B5: ABOUT THIS FILE
B6: This workbook is a teaching model that illustrates IFRS 17 (Insurance Contracts) through a progressive series of examples. It follows a single hypothetical insurance contract, a 3-year coverage period policy with 1,000 in upfront premiums, across four increasingly realistic scenarios. Each version builds two financial statements (Income Statement and Balance Sheet) so you can trace exactly how each new concept changes the numbers. The model decomposes the insurance liability into its IFRS 17 building blocks: Best Estimate Liability (BEL), Risk Adjustment (RA), and Contractual Service Margin (CSM), and shows how each block rolls forward period by period.
B8: MODEL STRUCTURE
B9: The workbook is organised into five progressive versions, each separated by a divider tab:
B11: Version | C11: Divider Tab | D11: Description | E11: Sheets
B12: v1: Simple Model | C12: Simple Model → | D12: The foundation case. A 3-year insurance contract with 1,000 in premiums collected upfront, 600 in expected claims, 150 in expected expenses, and a 90 Risk Adjustment, all at nominal value (0% discount rate). The CSM of 160 represents the unearned profit and is released evenly over 3 years. Claims and expenses are symmetric each period, so there is no experience variance. This version establishes the core IFRS 17 mechanics: no Day 1 profit (premiums create equal entries on asset and liability sides), and revenue emerges over time as the liability is released to the P&L. | E12: Assumptions (v1), P&L (v1), Balance Sheet (v1)
B13: v2: Add Discounting | C13: Add discounting → | D13: Builds on v1 by introducing a yield curve to discount future cash flows to present value. The BEL drops from 750 (nominal) to ~698 (discounted), which increases the CSM to ~212. Each period, the BEL and CSM accrete interest (discount unwind), and the model tracks BEL rollforward components: opening balance, expected outflow releases, accretion, and discount rate changes. Insurance finance income/expense flows entirely through P&L (no OCI election). This version shows how time value of money affects profit emergence and liability measurement. | E13: Assumptions (v2), P&L (v2), Balance Sheet (v2)
B14: v3: OCI Election | C14: OCI Election → | D14: Same contract and assumptions as v2, but elects to disaggregate insurance finance income/expense between P&L and OCI. The P&L shows only locked-in rate effects (BEL accretion and CSM accretion), while the effect of discount rate changes flows through Other Comprehensive Income. The Balance Sheet splits equity into Retained Earnings (from P&L) and Accumulated OCI (AOCI). Compare with v2 to see how the OCI election changes the presentation without affecting total comprehensive income or the balance sheet liability. | E14: Assumptions (v3), P&L (v3), Balance Sheet (v3)
B15: v4a: Experience Variance (no re-estimation) | C15: Experience Variance → | D15: Introduces a real-world complication: actual claims of 250/year exceed the expected 200/year, creating a 50/year experience variance. Critically, the insurer does NOT revise its future assumptions; it treats each year's overrun as a one-off. The BEL rollforward and CSM rollforward remain identical to v2 (since expectations are unchanged), but the P&L shows higher incurred claims, reducing net profit. This version isolates the impact of experience variance on the income statement without any feedback into the liability measurement. Compare with v4b to see how the same actual experience leads to very different financial statements depending on the re-estimation decision. | E15: Assumptions (v4a), P&L (v4a), Balance Sheet (v4a)
B16: v4b: Experience Variance (with re-estimation) | C16: Re-estimation (Option B) → | D16: Same actual cash flows as v4a: Year 1 claims are 250 vs. 200 expected, but here the insurer re-estimates future claims upward to 250/year for Years 2 and 3. This creates a BEL increase of ~95 at end of Year 1 (the present value of the additional 50/year for two remaining years). Under IFRS 17, this BEL increase is absorbed by the CSM, reducing it from ~145 to ~82, rather than hitting the P&L immediately (since the contract is not onerous). The CSM release in subsequent years is therefore lower, spreading the impact of adverse experience over the remaining coverage period. Compare with v4a to see how the re-estimation decision shifts profit timing. | E16: Assumptions (v4b), P&L (v4b), Balance Sheet (v4b)
B17: Bonus: Claim Development | C17: Claim Development → | D17: A bonus episode that sits at the end of the workbook. Its purpose is to show that under IFRS 17 it is the INCURRED date that drives the financial statements, not whether a claim has been paid in cash or still sits as a reserve. Same contract as v1 (no discounting, no experience variance), but cash payment of claims is split: 80% paid in the year incurred, 20% paid the following year. The P&L is identical to v1 because revenue and expense are recognised when claims are incurred, regardless of when cash leaves. The only changes are on the Balance Sheet: a Liability for Incurred Claims (Claims Payable) holds the unpaid portion, the insurance liability splits into LRC (remaining coverage) and LIC (incurred but unpaid), and a Year 4 column captures the tail payment from Year 3. This also brings the Balance Sheet closer to what you would see in a real-world insurer's accounts, where the LRC/LIC split is standard presentation. | E17: Assumptions (Claim Dev), P&L (Claim Dev), Balance Sheet (Claim Dev)
B18: KEY FEATURES
B19: • Each version contains a full set of Assumptions, P&L, and Balance Sheet sheets
B20: • Coloured divider tabs separate the versions for easy navigation
B21: • All financial statements are fully linked; changes in assumptions flow through automatically
B24: HOW TO USE
B25: Start with Version 1 to understand the building blocks (BEL, RA, CSM) and the core revenue recognition mechanics. Move to Version 2 to understand how discounting changes liability measurement, profit emergence, and introduces accretion. Version 3 shows how the OCI election changes the presentation of finance effects. Then compare Versions 4a and 4b side by side: they share the same actual cash flows but differ in whether the insurer re-estimates future assumptions. This contrast highlights the critical accounting policy choice and its impact on profit timing. In each version, compare the Assumptions tab to the prior version to see exactly what changed.
B28: Created by Francisco Martinez Checa, May 2026
B29: pacomc999@gmail.com

Sheet Simple Model →
A1: ← Simple / toy model tabs are to the right of this divider

Sheet Assumptions (v1)
A1: IFRS 17: Simple Insurance Example
A2: Simplifications:
A3: • Actual claims and expenses = expected each year (no experience variance)
A4: • No discounting (0% discount rate), all cash flows at nominal value
A5: • Assets consist solely of cash (no investment portfolio or investment income)
A6: • Claims and expenses are equal each year (symmetric risk profile)
A7: • Risk Adjustment released linearly over the coverage period
A9: Contract Details
A10: Coverage period (years) | B10: 3
A11: Discount rate | B11: 0
A13: Cash Flows at Inception | B13: Total | C13: Per Year
A14: Premiums collected (upfront) | B14: 1000
A15: Expected claims | B15: 600 | C15: =B15/B10 -> 200
A16: Expected expenses | B16: 150 | C16: =B16/B10 -> 50
A17: Risk Adjustment (total) | B17: 90 | C17: =B17/B10 -> 30
A19: Building Blocks at Inception
A20: BEL (Best Estimate Liability) | B20: =B15+B16 -> 750
A21: Risk Adjustment | B21: =B17 -> 90
A22: Contractual Service Margin (CSM) | B22: =B14-B20-B17 -> 160
A23: Total Insurance Liability at Inception | B23: =B20+B21+B22 -> 1000
A25: Release Pattern
A26: CSM release per year | B26: =B22/B10 -> 53.333333
A27: RA release per year | B27: =B17/B10 -> 30
A29: How it works:
A30: 1. The premium creates a balanced entry: cash +1,000 on the asset side and insurance liability +1,000 on the liability side
A31: The CSM acts as the plug that forces Day 1 profit to zero (Liability = BEL + RA + CSM = Premium)
A32: 2. Revenue then emerges over the coverage period as the liability components (BEL, RA, CSM) are released to the P&L
A33: 3. The CSM is the 'unearned profit'; it smooths profit recognition over the coverage period

Sheet P&L (v1)
A1: INCOME STATEMENT (P&L)
A2: Insurance Company: IFRS 17 Example
C4: 46022 | D4: 46387 | E4: 46752
A5: INSURANCE REVENUE
A6: BEL release: expected claims | C6: ='Assumptions (v1)'!C15 -> 200 | D6: ='Assumptions (v1)'!C15 -> 200 | E6: ='Assumptions (v1)'!C15 -> 200
A7: BEL release: expected expenses | C7: ='Assumptions (v1)'!C16 -> 50 | D7: ='Assumptions (v1)'!C16 -> 50 | E7: ='Assumptions (v1)'!C16 -> 50
A8: Risk Adjustment release | C8: ='Assumptions (v1)'!B27 -> 30 | D8: ='Assumptions (v1)'!B27 -> 30 | E8: ='Assumptions (v1)'!B27 -> 30
A9: CSM release (earned profit) | C9: ='Assumptions (v1)'!B26 -> 53.333333 | D9: ='Assumptions (v1)'!B26 -> 53.333333 | E9: ='Assumptions (v1)'!B26 -> 53.333333
A11: Total Insurance Revenue | C11: =SUM(C6:C9) -> 333.33333 | D11: =SUM(D6:D9) -> 333.33333 | E11: =SUM(E6:E9) -> 333.33333
A13: INSURANCE SERVICE EXPENSE
A14: Actual claims incurred | C14: ='Assumptions (v1)'!C15 -> 200 | D14: ='Assumptions (v1)'!C15 -> 200 | E14: ='Assumptions (v1)'!C15 -> 200
A15: Actual expenses incurred | C15: ='Assumptions (v1)'!C16 -> 50 | D15: ='Assumptions (v1)'!C16 -> 50 | E15: ='Assumptions (v1)'!C16 -> 50
A17: Total Insurance Service Expense | C17: =-(C14+C15) -> -250 | D17: =-(D14+D15) -> -250 | E17: =-(E14+E15) -> -250
A20: INSURANCE SERVICE RESULT | C20: =C11+C17 -> 83.333333 | D20: =D11+D17 -> 83.333333 | E20: =E11+E17 -> 83.333333
A22: Net Income | C22: =C20 -> 83.333333 | D22: =D20 -> 83.333333 | E22: =E20 -> 83.333333
A24: Cumulative Profit | C24: =C22 -> 83.333333 | D24: =C24+D22 -> 166.66667 | E24: =D24+E22 -> 250
A26: KEY INSIGHTS:
A27: ⚠️ Actual claims = Expected claims here (no experience variance). See v4a/v4b for what happens when actuals ≠ expected.
A28: Revenue ≠ Premiums! Revenue = expected costs released + RA released + CSM released
A29: The CSM release (53.3/yr) + RA release (30/yr) = 83.3 profit per year
A30: Total profit over 3 years = 250 = CSM (160) + RA (90)
A32: WORKINGS (not part of the P&L)
A33: Cash outflows (for BS link) | C33: Year 1 | D33: Year 2 | E33: Year 3
A34: Total cash paid out (claims + expenses) | C34: ='Assumptions (v1)'!C15+'Assumptions (v1)'!C16 -> 250 | D34: ='Assumptions (v1)'!C15+'Assumptions (v1)'!C16 -> 250 | E34: ='Assumptions (v1)'!C15+'Assumptions (v1)'!C16 -> 250
A35: In this model, cash outflows = insurance service expense because claims are paid immediately when incurred.
A36: In practice these can differ due to settlement lags, expense accruals, or upfront acquisition costs.
A37: The BS cash line references cash outflows (not P&L expense) because it tracks actual cash movements.

Sheet Balance Sheet (v1)
A1: BALANCE SHEET
A2: Insurance Company: IFRS 17 Example
B4: 45658 | C4: 46022 | D4: 46387 | E4: 46752
A5: ASSETS
A6: Cash & Investments ← 1,000 premium received upfront | B6: ='Assumptions (v1)'!B14 -> 1000 | C6: =B6-'P&L (v1)'!C34 -> 750 | D6: =C6-'P&L (v1)'!D34 -> 500 | E6: =D6-'P&L (v1)'!E34 -> 250
A7: Total Assets | B7: =B6 -> 1000 | C7: =C6 -> 750 | D7: =D6 -> 500 | E7: =E6 -> 250
A9: LIABILITIES
A10: Insurance Contract Liability:
A11: BEL (Best Estimate Liability) | B11: ='Assumptions (v1)'!B20 -> 750 | C11: =B11-'P&L (v1)'!C6-'P&L (v1)'!C7 -> 500 | D11: =C11-'P&L (v1)'!D6-'P&L (v1)'!D7 -> 250 | E11: =D11-'P&L (v1)'!E6-'P&L (v1)'!E7 -> 0
A12: Risk Adjustment | B12: ='Assumptions (v1)'!B21 -> 90 | C12: =B12-'P&L (v1)'!C8 -> 60 | D12: =C12-'P&L (v1)'!D8 -> 30 | E12: =D12-'P&L (v1)'!E8 -> 0
A13: Fulfilment Cash Flows (BEL + RA) | B13: =B11+B12 -> 840 | C13: =C11+C12 -> 560 | D13: =D11+D12 -> 280 | E13: =E11+E12 -> 0
A14: Contractual Service Margin (CSM) | B14: ='Assumptions (v1)'!B22 -> 160 | C14: =B14-'P&L (v1)'!C9 -> 106.66667 | D14: =C14-'P&L (v1)'!D9 -> 53.333333 | E14: =D14-'P&L (v1)'!E9 -> 0
A15: Total Insurance Liability | B15: =B11+B12+B14 -> 1000 | C15: =C11+C12+C14 -> 666.66667 | D15: =D11+D12+D14 -> 333.33333 | E15: =E11+E12+E14 -> 0
A16: Total Liabilities | B16: =B15 -> 1000 | C16: =C15 -> 666.66667 | D16: =D15 -> 333.33333 | E16: =E15 -> 0
A18: EQUITY
A19: Retained Earnings | B19: 0 | C19: =B19+'P&L (v1)'!C22 -> 83.333333 | D19: =C19+'P&L (v1)'!D22 -> 166.66667 | E19: =D19+'P&L (v1)'!E22 -> 250
A20: Total Equity | B20: =B19 -> 0 | C20: =C19 -> 83.333333 | D20: =D19 -> 166.66667 | E20: =E19 -> 250
A22: CHECK: Assets = Liabilities + Equity | B22: =IF(ABS(B7-B16-B20)<0.01,"✅ Balanced","❌ Error") -> ✅ Balanced | C22: =IF(ABS(C7-C16-C20)<0.01,"✅ Balanced","❌ Error") -> ✅ Balanced | D22: =IF(ABS(D7-D16-D20)<0.01,"✅ Balanced","❌ Error") -> ✅ Balanced | E22: =IF(ABS(E7-E16-E20)<0.01,"✅ Balanced","❌ Error") -> ✅ Balanced

Sheet Add discounting →

Sheet Assumptions (v2)
A1: IFRS 17: Example with discounting
A2: Simplifications:
A3: • Assets consist solely of cash (no investment portfolio or investment income)
A4: • All insurance finance income/expense flows through P&L (no OCI election)
A5: • Claims and expenses are equal each year; RA released linearly
A7: CONTRACT DETAILS
A8: Coverage period (years) | C8: 3
A9: Premiums collected (upfront) | C9: 1000
A11: UNDISCOUNTED CASH FLOWS | C11: Total | D11: 46022 | E11: 46387 | F11: 46752
A12: Expected claims | C12: 600 | D12: =C12/C8 -> 200 | E12: =C12/C8 -> 200 | F12: =C12/C8 -> 200
A13: Expected expenses | C13: 150 | D13: =C13/C8 -> 50 | E13: =C13/C8 -> 50 | F13: =C13/C8 -> 50
A14: Total undiscounted outflows | C14: =C12+C13 -> 750 | D14: =D12+D13 -> 250 | E14: =E12+E13 -> 250 | F14: =F12+F13 -> 250
A15: Risk Adjustment (total, undiscounted) | C15: 90
A17: YIELD CURVE (Spot Rates) | D17: 1Y Spot | E17: 2Y Spot | F17: 3Y Spot
A18: Curve at Inception (t=0) | C18: ← blue = input | D18: 0.03 | E18: 0.035 | F18: 0.04
A19: Curve at End Year 1 (t=1) | D19: 0.0325 | E19: 0.0375
A20: Curve at End Year 2 (t=2) | D20: 0.035
A22: DISCOUNT FACTORS | D22: DF 1Y | E22: DF 2Y | F22: DF 3Y
A23: DFs at Inception (t=0) | D23: =1/(1+D18)^1 -> 0.97087379 | E23: =1/(1+E18)^2 -> 0.9335107 | F23: =1/(1+F18)^3 -> 0.88899636
A24: DFs at End Year 1 (t=1) | D24: =1/(1+D19)^1 -> 0.968523 | E24: =1/(1+E19)^2 -> 0.92901727
A25: DFs at End Year 2 (t=2) | D25: =1/(1+D20)^1 -> 0.96618357
A27: BEL (DISCOUNTED) AT EACH DATE | D27: PV of Y1 CFs | E27: PV of Y2 CFs | F27: PV of Y3 CFs | G27: BEL Total
A28: BEL at Inception (t=0) | D28: =D14*D23 -> 242.71845 | E28: =E14*E23 -> 233.37768 | F28: =F14*F23 -> 222.24909 | G28: =SUM(D28:F28) -> 698.34521
A29: BEL at End Year 1 (t=1), using NEW curve | E29: =E14*D24 -> 242.13075 | F29: =F14*E24 -> 232.25432 | G29: =SUM(E29:F29) -> 474.38507
A30: BEL at End Year 2 (t=2), using NEW curve | F30: =F14*D25 -> 241.54589 | G30: =F30 -> 241.54589
A31: BEL at End Year 3 (t=3), using NEW curve | G31: 0
A33: BEL at End Year 1, using OLD curve (for accretion calc) | E33: =E14*D23 -> 242.71845 | F33: =F14*E23 -> 233.37768 | G33: =SUM(E33:F33) -> 476.09612
A34: BEL at End Year 2, using OLD curve (for accretion calc) | F34: =F14*D23 -> 242.71845 | G34: =F34 -> 242.71845
A36: BEL ROLLFORWARD COMPONENTS | D36: 46022 | E36: 46387 | F36: 46752
A37: Opening BEL | D37: =G28 -> 698.34521 | E37: =G29 -> 474.38507 | F37: =G30 -> 241.54589
A38: Less: BEL release (expected outflows for the year) | D38: =-D14 -> -250 | E38: =-E14 -> -250 | F38: =-F14 -> -250
A39: Accretion (discount unwind) | D39: =G33-(G28-D14) -> 27.75091 | E39: =G34-(G29-E14) -> 18.333378 | F39: =G31-(G30-F14) -> 8.4541063
A40: Effect of discount rate changes | D40: =G29-G33 -> -1.7110526 | E40: =G30-G34 -> -1.1725529 | F40: 0
A41: Closing BEL | D41: =SUM(D37:D40) -> 474.38507 | E41: =SUM(E37:E40) -> 241.54589 | F41: =SUM(F37:F40) -> 0
A42: CHECK: Closing BEL ties to BEL calc above | D42: =IF(ABS(D41-G29)<0.01,"✅","❌") -> ✅ | E42: =IF(ABS(E41-G30)<0.01,"✅","❌") -> ✅ | F42: =IF(ABS(F41-G31)<0.01,"✅","❌") -> ✅
A44: RISK ADJUSTMENT
A45: RA at Inception | C45: =C15 -> 90
A46: RA release per year (evenly over coverage) | C46: =C45/C8 -> 30
A48: BUILDING BLOCKS AT INCEPTION
A49: BEL (discounted) | C49: =G28 -> 698.34521
...

Sheet P&L (v2)
A1: INCOME STATEMENT (P&L)
A2: IFRS 17: Model with Discounting
C4: 46022 | D4: 46387 | E4: 46752
A5: INSURANCE REVENUE
A6: BEL release: expected claims | C6: ='Assumptions (v2)'!D12 -> 200 | D6: ='Assumptions (v2)'!E12 -> 200 | E6: ='Assumptions (v2)'!F12 -> 200
A7: BEL release: expected expenses | C7: ='Assumptions (v2)'!D13 -> 50 | D7: ='Assumptions (v2)'!E13 -> 50 | E7: ='Assumptions (v2)'!F13 -> 50
A8: Risk Adjustment release | C8: ='Assumptions (v2)'!C46 -> 30 | D8: ='Assumptions (v2)'!C46 -> 30 | E8: ='Assumptions (v2)'!C46 -> 30
A9: CSM release (earned profit) | C9: =-'Assumptions (v2)'!D59 -> 72.668144 | D9: =-'Assumptions (v2)'!E59 -> 74.848188 | E9: =-'Assumptions (v2)'!F59 -> 77.093634
A11: Total Insurance Revenue | C11: =SUM(C6:C9) -> 352.66814 | D11: =SUM(D6:D9) -> 354.84819 | E11: =SUM(E6:E9) -> 357.09363
A13: INSURANCE SERVICE EXPENSE
A14: Actual claims incurred | C14: ='Assumptions (v2)'!D12 -> 200 | D14: ='Assumptions (v2)'!E12 -> 200 | E14: ='Assumptions (v2)'!F12 -> 200
A15: Actual expenses incurred | C15: ='Assumptions (v2)'!D13 -> 50 | D15: ='Assumptions (v2)'!E13 -> 50 | E15: ='Assumptions (v2)'!F13 -> 50
A17: Total Insurance Service Expense | C17: =-(C14+C15) -> -250 | D17: =-(D14+D15) -> -250 | E17: =-(E14+E15) -> -250
A19: INSURANCE SERVICE RESULT | C19: =C11+C17 -> 102.66814 | D19: =D11+D17 -> 104.84819 | E19: =E11+E17 -> 107.09363
A21: INSURANCE FINANCE INCOME / (EXPENSE)
A22: Accretion of BEL (discount unwind) | C22: =-'Assumptions (v2)'!D39 -> -27.75091 | D22: =-'Assumptions (v2)'!E39 -> -18.333378 | E22: =-'Assumptions (v2)'!F39 -> -8.4541063
A23: Effect of discount rate changes | C23: =-'Assumptions (v2)'!D40 -> 1.7110526 | D23: =-'Assumptions (v2)'!E40 -> 1.1725529 | E23: =-'Assumptions (v2)'!F40 -> 0
A24: Accretion of CSM | C24: =-'Assumptions (v2)'!D57 -> -6.3496437 | D24: =-'Assumptions (v2)'!E57 -> -4.3600886 | E24: =-'Assumptions (v2)'!F57 -> -2.2454457
A25: Total Insurance Finance Income / (Expense) | C25: =SUM(C22:C24) -> -32.389501 | D25: =SUM(D22:D24) -> -21.520913 | E25: =SUM(E22:E24) -> -10.699552
A27: NET INCOME | C27: =C19+C25 -> 70.278643 | D27: =D19+D25 -> 83.327275 | E27: =E19+E25 -> 96.394082
A29: Cumulative Profit | C29: =C27 -> 70.278643 | D29: =C29+D27 -> 153.60592 | E29: =D29+E27 -> 250
A31: KEY INSIGHTS:
A32: Discounting reduces the BEL from 750 (nominal) to ~698, increasing the CSM from 160 to ~212. More profit is deferred at inception.
A33: Accretion (discount unwind) creates an insurance finance expense each period as the BEL 'grows back' toward its undiscounted value.
A34: CSM release is no longer equal each year: it increases over time because CSM accretes interest before each release.
A35: Net income still totals 250 over the contract, but profit emergence is shifted: less in Year 1, more in Year 3.
A36: The yield curve shift of +25bps per year creates non-zero discount rate change effects, flowing through Insurance Finance I/E.
A37: Compare with v1: same contract, same total profit, but discounting changes the timing and introduces finance income/expense.
A39: WORKINGS (not part of the P&L)
A40: Cash outflows (for BS link)
A41: Total cash paid out (claims + expenses) | C41: ='Assumptions (v2)'!D14 -> 250 | D41: ='Assumptions (v2)'!E14 -> 250 | E41: ='Assumptions (v2)'!F14 -> 250
A42: In this model, cash outflows = insurance service expense because claims are paid immediately when incurred.
A43: In practice these can differ due to settlement lags, expense accruals, or upfront acquisition costs.
A44: The BS cash line references cash outflows (not P&L expense) because it tracks actual cash movements.

Sheet Balance Sheet (v2)
A1: BALANCE SHEET
A2: IFRS 17: Model with Discounting
B4: 45658 | C4: 46022 | D4: 46387 | E4: 46752
A5: ASSETS
A6: Cash & Investments | B6: ='Assumptions (v2)'!C9 -> 1000 | C6: =B6-'P&L (v2)'!C41 -> 750 | D6: =C6-'P&L (v2)'!D41 -> 500 | E6: =D6-'P&L (v2)'!E41 -> 250
A7: Total Assets | B7: =B6 -> 1000 | C7: =C6 -> 750 | D7: =D6 -> 500 | E7: =E6 -> 250
A9: LIABILITIES
A10: Insurance Contract Liability:
A11: BEL (Best Estimate Liability) | B11: ='Assumptions (v2)'!G28 -> 698.34521 | C11: ='Assumptions (v2)'!G29 -> 474.38507 | D11: ='Assumptions (v2)'!G30 -> 241.54589 | E11: ='Assumptions (v2)'!G31 -> 0
A12: Risk Adjustment | B12: ='Assumptions (v2)'!C50 -> 90 | C12: =B12-'P&L (v2)'!C8 -> 60 | D12: =C12-'P&L (v2)'!D8 -> 30 | E12: =D12-'P&L (v2)'!E8 -> 0
A13: Fulfilment Cash Flows (BEL + RA) | B13: =B11+B12 -> 788.34521 | C13: =C11+C12 -> 534.38507 | D13: =D11+D12 -> 271.54589 | E13: =E11+E12 -> 0
A14: Contractual Service Margin (CSM) | B14: ='Assumptions (v2)'!C52 -> 211.65479 | C14: ='Assumptions (v2)'!D60 -> 145.33629 | D14: ='Assumptions (v2)'!E60 -> 74.848188 | E14: ='Assumptions (v2)'!F60 -> 0
A15: Total Insurance Liability | B15: =B13+B14 -> 1000 | C15: =C13+C14 -> 679.72136 | D15: =D13+D14 -> 346.39408 | E15: =E13+E14 -> 0
A16: Total Liabilities | B16: =B15 -> 1000 | C16: =C15 -> 679.72136 | D16: =D15 -> 346.39408 | E16: =E15 -> 0
A18: EQUITY
A19: Retained Earnings | B19: 0 | C19: =B19+'P&L (v2)'!C27 -> 70.278643 | D19: =C19+'P&L (v2)'!D27 -> 153.60592 | E19: =D19+'P&L (v2)'!E27 -> 250
A20: Total Equity | B20: =B19 -> 0 | C20: =C19 -> 70.278643 | D20: =D19 -> 153.60592 | E20: =E19 -> 250
A22: CHECK: Assets = Liabilities + Equity | B22: =IF(ABS(B7-B16-B20)<0.01,"✅ Balanced","❌ "&TEXT(B7-B16-B20,"#,##0.00")) -> ✅ Balanced | C22: =IF(ABS(C7-C16-C20)<0.01,"✅ Balanced","❌ "&TEXT(C7-C16-C20,"#,##0.00")) -> ✅ Balanced | D22: =IF(ABS(D7-D16-D20)<0.01,"✅ Balanced","❌ "&TEXT(D7-D16-D20,"#,##0.00")) -> ✅ Balanced | E22: =IF(ABS(E7-E16-E20)<0.01,"✅ Balanced","❌ "&TEXT(E7-E16-E20,"#,##0.00")) -> ✅ Balanced

Sheet OCI Election →

Sheet Assumptions (v3)
A1: IFRS 17: Example with discounting (OCI Election)
A2: Simplifications:
A3: • Assets consist solely of cash (no investment portfolio or investment income)
A4: • All insurance finance income/expense: P&L uses locked-in rate; discount rate changes flow through OCI
A5: • Claims and expenses are equal each year; RA released linearly
A7: CONTRACT DETAILS
A8: Coverage period (years) | C8: 3
A9: Premiums collected (upfront) | C9: 1000
A11: UNDISCOUNTED CASH FLOWS | C11: Total | D11: 46022 | E11: 46387 | F11: 46752
A12: Expected claims | C12: 600 | D12: =C12/C8 -> 200 | E12: =C12/C8 -> 200 | F12: =C12/C8 -> 200
A13: Expected expenses | C13: 150 | D13: =C13/C8 -> 50 | E13: =C13/C8 -> 50 | F13: =C13/C8 -> 50
A14: Total undiscounted outflows | C14: =C12+C13 -> 750 | D14: =D12+D13 -> 250 | E14: =E12+E13 -> 250 | F14: =F12+F13 -> 250
A15: Risk Adjustment (total, undiscounted) | C15: 90
A17: YIELD CURVE (Spot Rates) | D17: 1Y Spot | E17: 2Y Spot | F17: 3Y Spot
A18: Curve at Inception (t=0) | C18: ← blue = input | D18: 0.03 | E18: 0.035 | F18: 0.04
A19: Curve at End Year 1 (t=1) | D19: 0.0325 | E19: 0.0375
A20: Curve at End Year 2 (t=2) | D20: 0.035
A22: DISCOUNT FACTORS | D22: DF 1Y | E22: DF 2Y | F22: DF 3Y
A23: DFs at Inception (t=0) | D23: =1/(1+D18)^1 -> 0.97087379 | E23: =1/(1+E18)^2 -> 0.9335107 | F23: =1/(1+F18)^3 -> 0.88899636
A24: DFs at End Year 1 (t=1) | D24: =1/(1+D19)^1 -> 0.968523 | E24: =1/(1+E19)^2 -> 0.92901727
A25: DFs at End Year 2 (t=2) | D25: =1/(1+D20)^1 -> 0.96618357
A27: BEL (DISCOUNTED) AT EACH DATE | D27: PV of Y1 CFs | E27: PV of Y2 CFs | F27: PV of Y3 CFs | G27: BEL Total
A28: BEL at Inception (t=0) | D28: =D14*D23 -> 242.71845 | E28: =E14*E23 -> 233.37768 | F28: =F14*F23 -> 222.24909 | G28: =SUM(D28:F28) -> 698.34521
A29: BEL at End Year 1 (t=1), using NEW curve | E29: =E14*D24 -> 242.13075 | F29: =F14*E24 -> 232.25432 | G29: =SUM(E29:F29) -> 474.38507
A30: BEL at End Year 2 (t=2), using NEW curve | F30: =F14*D25 -> 241.54589 | G30: =F30 -> 241.54589
A31: BEL at End Year 3 (t=3), using NEW curve | G31: 0
A33: BEL at End Year 1, using OLD curve (for accretion calc) | E33: =E14*D23 -> 242.71845 | F33: =F14*E23 -> 233.37768 | G33: =SUM(E33:F33) -> 476.09612
A34: BEL at End Year 2, using OLD curve (for accretion calc) | F34: =F14*D23 -> 242.71845 | G34: =F34 -> 242.71845
A36: BEL ROLLFORWARD COMPONENTS | D36: 46022 | E36: 46387 | F36: 46752
A37: Opening BEL | D37: =G28 -> 698.34521 | E37: =G29 -> 474.38507 | F37: =G30 -> 241.54589
A38: Less: BEL release (expected outflows for the year) | D38: =-D14 -> -250 | E38: =-E14 -> -250 | F38: =-F14 -> -250
A39: Accretion (discount unwind) | D39: =G33-(G28-D14) -> 27.75091 | E39: =G34-(G29-E14) -> 18.333378 | F39: =G31-(G30-F14) -> 8.4541063
A40: Effect of discount rate changes | D40: =G29-G33 -> -1.7110526 | E40: =G30-G34 -> -1.1725529 | F40: 0
A41: Closing BEL | D41: =SUM(D37:D40) -> 474.38507 | E41: =SUM(E37:E40) -> 241.54589 | F41: =SUM(F37:F40) -> 0
A42: CHECK: Closing BEL ties to BEL calc above | D42: =IF(ABS(D41-G29)<0.01,"✅","❌") -> ✅ | E42: =IF(ABS(E41-G30)<0.01,"✅","❌") -> ✅ | F42: =IF(ABS(F41-G31)<0.01,"✅","❌") -> ✅
A44: RISK ADJUSTMENT
A45: RA at Inception | C45: =C15 -> 90
A46: RA release per year (evenly over coverage) | C46: =C45/C8 -> 30
A48: BUILDING BLOCKS AT INCEPTION
A49: BEL (discounted) | C49: =G28 -> 698.34521
...

Sheet P&L (v3)
A1: INCOME STATEMENT (P&L)
A2: IFRS 17: Discounting with OCI Election
C4: 46022 | D4: 46387 | E4: 46752
A5: INSURANCE REVENUE
A6: BEL release: expected claims | C6: ='Assumptions (v3)'!D12 -> 200 | D6: ='Assumptions (v3)'!E12 -> 200 | E6: ='Assumptions (v3)'!F12 -> 200
A7: BEL release: expected expenses | C7: ='Assumptions (v3)'!D13 -> 50 | D7: ='Assumptions (v3)'!E13 -> 50 | E7: ='Assumptions (v3)'!F13 -> 50
A8: Risk Adjustment release | C8: ='Assumptions (v3)'!C46 -> 30 | D8: ='Assumptions (v3)'!C46 -> 30 | E8: ='Assumptions (v3)'!C46 -> 30
A9: CSM release (earned profit) | C9: =-'Assumptions (v3)'!D59 -> 72.668144 | D9: =-'Assumptions (v3)'!E59 -> 74.848188 | E9: =-'Assumptions (v3)'!F59 -> 77.093634
A11: Total Insurance Revenue | C11: =SUM(C6:C9) -> 352.66814 | D11: =SUM(D6:D9) -> 354.84819 | E11: =SUM(E6:E9) -> 357.09363
A13: INSURANCE SERVICE EXPENSE
A14: Actual claims incurred | C14: ='Assumptions (v3)'!D12 -> 200 | D14: ='Assumptions (v3)'!E12 -> 200 | E14: ='Assumptions (v3)'!F12 -> 200
A15: Actual expenses incurred | C15: ='Assumptions (v3)'!D13 -> 50 | D15: ='Assumptions (v3)'!E13 -> 50 | E15: ='Assumptions (v3)'!F13 -> 50
A17: Total Insurance Service Expense | C17: =-(C14+C15) -> -250 | D17: =-(D14+D15) -> -250 | E17: =-(E14+E15) -> -250
A19: INSURANCE SERVICE RESULT | C19: =C11+C17 -> 102.66814 | D19: =D11+D17 -> 104.84819 | E19: =E11+E17 -> 107.09363
A21: INSURANCE FINANCE INCOME / (EXPENSE), in P&L
A22: Accretion of BEL (discount unwind at locked-in rate) | C22: =-'Assumptions (v3)'!D39 -> -27.75091 | D22: =-'Assumptions (v3)'!E39 -> -18.333378 | E22: =-'Assumptions (v3)'!F39 -> -8.4541063
A23: Accretion of CSM (at locked-in rate) | C23: =-'Assumptions (v3)'!D57 -> -6.3496437 | D23: =-'Assumptions (v3)'!E57 -> -4.3600886 | E23: =-'Assumptions (v3)'!F57 -> -2.2454457
A24: Total Insurance Finance I/E in P&L | C24: =SUM(C22:C23) -> -34.100554 | D24: =SUM(D22:D23) -> -22.693466 | E24: =SUM(E22:E23) -> -10.699552
A26: NET INCOME | C26: =C19+C24 -> 68.56759 | D26: =D19+D24 -> 82.154722 | E26: =E19+E24 -> 96.394082
A28: Cumulative Retained Earnings | C28: =C26 -> 68.56759 | D28: =C28+D26 -> 150.72231 | E28: =D28+E26 -> 247.11639
A30: OTHER COMPREHENSIVE INCOME (OCI) ← not part of the P&L; reported separately
A31: Effect of discount rate changes on BEL | C31: =-'Assumptions (v3)'!D40 -> 1.7110526 | D31: =-'Assumptions (v3)'!E40 -> 1.1725529 | E31: =-'Assumptions (v3)'!F40 -> 0
A32: Total OCI | C32: =C31 -> 1.7110526 | D32: =D31 -> 1.1725529 | E32: =E31 -> 0
A34: TOTAL COMPREHENSIVE INCOME | C34: =C26+C32 -> 70.278643 | D34: =D26+D32 -> 83.327275 | E34: =E26+E32 -> 96.394082
A36: Cumulative Comprehensive Income | C36: =C34 -> 70.278643 | D36: =C36+D34 -> 153.60592 | E36: =D36+E34 -> 250
A39: KEY INSIGHTS:
A40: The OCI election splits insurance finance effects: P&L shows only locked-in rate accretion (predictable); discount rate changes bypass P&L entirely.
A41: This reduces P&L volatility: if rates spike, the impact sits in AOCI on the balance sheet, not in Net Income.
A42: Equity is no longer explained by the P&L alone. Retained Earnings = cumulative Net Income; AOCI = cumulative OCI. You need both to reconcile Total Equity.
A43: Total Comprehensive Income (Net Income + OCI) equals v2's Net Income. The total profit is identical; the OCI election only changes which line it appears on.
A45: WORKINGS (not part of the P&L)
A46: Cash outflows (for BS link)
A47: Total cash paid out (claims + expenses) | C47: ='Assumptions (v3)'!D14 -> 250 | D47: ='Assumptions (v3)'!E14 -> 250 | E47: ='Assumptions (v3)'!F14 -> 250
A48: In this model, cash outflows = insurance service expense because claims are paid immediately when incurred.
A49: In practice these can differ due to settlement lags, expense accruals, or upfront acquisition costs.
A50: The BS cash line references cash outflows (not P&L expense) because it tracks actual cash movements.

Sheet Balance Sheet (v3)
A1: BALANCE SHEET
A2: IFRS 17: Discounting with OCI Election
B4: 45658 | C4: 46022 | D4: 46387 | E4: 46752
A5: ASSETS
A6: Cash & Investments | B6: ='Assumptions (v3)'!C9 -> 1000 | C6: =B6-'P&L (v3)'!C47 -> 750 | D6: =C6-'P&L (v3)'!D47 -> 500 | E6: =D6-'P&L (v3)'!E47 -> 250
A7: Total Assets | B7: =B6 -> 1000 | C7: =C6 -> 750 | D7: =D6 -> 500 | E7: =E6 -> 250
A9: LIABILITIES
A10: Insurance Contract Liability:
A11: BEL (Best Estimate Liability) | B11: ='Assumptions (v3)'!G28 -> 698.34521 | C11: ='Assumptions (v3)'!G29 -> 474.38507 | D11: ='Assumptions (v3)'!G30 -> 241.54589 | E11: ='Assumptions (v3)'!G31 -> 0
A12: Risk Adjustment | B12: ='Assumptions (v3)'!C50 -> 90 | C12: =B12-'P&L (v3)'!C8 -> 60 | D12: =C12-'P&L (v3)'!D8 -> 30 | E12: =D12-'P&L (v3)'!E8 -> 0
A13: Fulfilment Cash Flows (BEL + RA) | B13: =B11+B12 -> 788.34521 | C13: =C11+C12 -> 534.38507 | D13: =D11+D12 -> 271.54589 | E13: =E11+E12 -> 0
A14: Contractual Service Margin (CSM) | B14: ='Assumptions (v3)'!C52 -> 211.65479 | C14: ='Assumptions (v3)'!D60 -> 145.33629 | D14: ='Assumptions (v3)'!E60 -> 74.848188 | E14: ='Assumptions (v3)'!F60 -> 0
A15: Total Insurance Liability | B15: =B13+B14 -> 1000 | C15: =C13+C14 -> 679.72136 | D15: =D13+D14 -> 346.39408 | E15: =E13+E14 -> 0
A16: Total Liabilities | B16: =B15 -> 1000 | C16: =C15 -> 679.72136 | D16: =D15 -> 346.39408 | E16: =E15 -> 0
A18: EQUITY
A19: Retained Earnings | B19: 0 | C19: =B19+'P&L (v3)'!C26 -> 68.56759 | D19: =C19+'P&L (v3)'!D26 -> 150.72231 | E19: =D19+'P&L (v3)'!E26 -> 247.11639
A20: Accumulated OCI (AOCI) | B20: 0 | C20: =B20+'P&L (v3)'!C32 -> 1.7110526 | D20: =C20+'P&L (v3)'!D32 -> 2.8836055 | E20: =D20+'P&L (v3)'!E32 -> 2.8836055
A21: Total Equity | B21: =B19+B20 -> 0 | C21: =C19+C20 -> 70.278643 | D21: =D19+D20 -> 153.60592 | E21: =E19+E20 -> 250
A23: CHECK: Assets = Liabilities + Equity | B23: =IF(ABS(B7-B16-B21)<0.01,"✅ Balanced","❌ "&TEXT(B7-B16-B21,"#,##0.00")) -> ✅ Balanced | C23: =IF(ABS(C7-C16-C21)<0.01,"✅ Balanced","❌ "&TEXT(C7-C16-C21,"#,##0.00")) -> ✅ Balanced | D23: =IF(ABS(D7-D16-D21)<0.01,"✅ Balanced","❌ "&TEXT(D7-D16-D21,"#,##0.00")) -> ✅ Balanced | E23: =IF(ABS(E7-E16-E21)<0.01,"✅ Balanced","❌ "&TEXT(E7-E16-E21,"#,##0.00")) -> ✅ Balanced
A25: KEY INSIGHTS:
A26: Equity splits into two components: Retained Earnings (driven by Net Income from the P&L) and AOCI (driven by OCI, which bypasses the P&L).
A27: The P&L alone does not explain total equity changes. To reconcile the movement in Total Equity, you need Total Comprehensive Income = Net Income + OCI.
A28: AOCI accumulates discount rate change effects that were excluded from P&L. It unwinds to zero by contract end when all cash flows are settled.
A29: Total Equity (250) equals v2's Total Equity. The OCI election changes how equity is decomposed, not its total.

Sheet Experience Variance →

Sheet Assumptions (v4a)
A1: IFRS 17: Experience Variance (Option A)
A2: Simplifications:
A3: • Actual claims exceed expected, but insurer does NOT re-estimate future claims
A4: • Assets consist solely of cash (no investment portfolio or investment income)
A5: • All insurance finance income/expense flows through P&L (no OCI election)
A7: CONTRACT DETAILS
A8: Coverage period (years) | C8: 3
A9: Premiums collected (upfront) | C9: 1000
A11: EXPECTED CASH FLOWS (at inception) | C11: Total | D11: 46022 | E11: 46387 | F11: 46752
A12: Expected claims | C12: 600 | D12: =C12/C8 -> 200 | E12: =C12/C8 -> 200 | F12: =C12/C8 -> 200
A13: Expected expenses | C13: 150 | D13: =C13/C8 -> 50 | E13: =C13/C8 -> 50 | F13: =C13/C8 -> 50
A14: Total expected undiscounted outflows | C14: =C12+C13 -> 750 | D14: =D12+D13 -> 250 | E14: =E12+E13 -> 250 | F14: =F12+F13 -> 250
A15: Risk Adjustment (total, undiscounted) | C15: 90
A17: ACTUAL CASH FLOWS | D17: 46022 | E17: 46387 | F17: 46752
A18: Actual claims | D18: 250 | E18: 250 | F18: 250
A19: Actual expenses | D19: =D13 -> 50 | E19: =E13 -> 50 | F19: =F13 -> 50
A20: Total actual outflows | D20: =D18+D19 -> 300 | E20: =E18+E19 -> 300 | F20: =F18+F19 -> 300
A22: YIELD CURVE (Spot Rates) | D22: 1Y Spot | E22: 2Y Spot | F22: 3Y Spot
A23: Curve at Inception (t=0) | C23: ← blue = input | D23: 0.03 | E23: 0.035 | F23: 0.04
A24: Curve at End Year 1 (t=1) | D24: 0.03 | E24: 0.035
A25: Curve at End Year 2 (t=2) | D25: 0.03
A27: DISCOUNT FACTORS | D27: DF 1Y | E27: DF 2Y | F27: DF 3Y
A28: DFs at Inception (t=0) | D28: =1/(1+D23)^1 -> 0.97087379 | E28: =1/(1+E23)^2 -> 0.9335107 | F28: =1/(1+F23)^3 -> 0.88899636
A29: DFs at End Year 1 (t=1) | D29: =1/(1+D24)^1 -> 0.97087379 | E29: =1/(1+E24)^2 -> 0.9335107
A30: DFs at End Year 2 (t=2) | D30: =1/(1+D25)^1 -> 0.97087379
A32: BEL (DISCOUNTED) AT EACH DATE | D32: PV of Y1 CFs | E32: PV of Y2 CFs | F32: PV of Y3 CFs | G32: BEL Total
A33: BEL at Inception (t=0) | D33: =D14*D28 -> 242.71845 | E33: =E14*E28 -> 233.37768 | F33: =F14*F28 -> 222.24909 | G33: =SUM(D33:F33) -> 698.34521
A34: BEL at End Year 1 (t=1), using NEW curve | E34: =E14*D29 -> 242.71845 | F34: =F14*E29 -> 233.37768 | G34: =SUM(E34:F34) -> 476.09612
A35: BEL at End Year 2 (t=2), using NEW curve | F35: =F14*D30 -> 242.71845 | G35: =F35 -> 242.71845
A36: BEL at End Year 3 (t=3), using NEW curve | G36: 0
A38: BEL at End Year 1, using OLD curve (for accretion calc) | E38: =E14*D28 -> 242.71845 | F38: =F14*E28 -> 233.37768 | G38: =SUM(E38:F38) -> 476.09612
A39: BEL at End Year 2, using OLD curve (for accretion calc) | F39: =F14*D28 -> 242.71845 | G39: =F39 -> 242.71845
A41: BEL ROLLFORWARD COMPONENTS | D41: 46022 | E41: 46387 | F41: 46752
A42: Opening BEL | D42: =G33 -> 698.34521 | E42: =G34 -> 476.09612 | F42: =G35 -> 242.71845
A43: Less: BEL release (expected outflows for the year) | D43: =-D14 -> -250 | E43: =-E14 -> -250 | F43: =-F14 -> -250
A44: Accretion (discount unwind) | D44: =G38-(G33-D14) -> 27.75091 | E44: =G39-(G34-E14) -> 16.622325 | F44: =G36-(G35-F14) -> 7.2815534
A45: Effect of discount rate changes | D45: =G34-G38 -> 0 | E45: =G35-G39 -> 0 | F45: 0
A46: Closing BEL | D46: =SUM(D42:D45) -> 476.09612 | E46: =SUM(E42:E45) -> 242.71845 | F46: =SUM(F42:F45) -> 0
A47: CHECK: Closing BEL ties to BEL calc above | D47: =IF(ABS(D46-G34)<0.01,"✅","❌") -> ✅ | E47: =IF(ABS(E46-G35)<0.01,"✅","❌") -> ✅ | F47: =IF(ABS(F46-G36)<0.01,"✅","❌") -> ✅
A49: RISK ADJUSTMENT
...

Sheet P&L (v4a)
A1: INCOME STATEMENT (P&L)
A2: IFRS 17: Experience Variance (Option A)
C4: 46022 | D4: 46387 | E4: 46752
A5: INSURANCE REVENUE
A6: BEL release: expected claims | C6: ='Assumptions (v4a)'!D12 -> 200 | D6: ='Assumptions (v4a)'!E12 -> 200 | E6: ='Assumptions (v4a)'!F12 -> 200
A7: BEL release: expected expenses | C7: ='Assumptions (v4a)'!D13 -> 50 | D7: ='Assumptions (v4a)'!E13 -> 50 | E7: ='Assumptions (v4a)'!F13 -> 50
A8: Risk Adjustment release | C8: ='Assumptions (v4a)'!C51 -> 30 | D8: ='Assumptions (v4a)'!C51 -> 30 | E8: ='Assumptions (v4a)'!C51 -> 30
A9: CSM release (earned profit) | C9: =-'Assumptions (v4a)'!D64 -> 72.668144 | D9: =-'Assumptions (v4a)'!E64 -> 74.848188 | E9: =-'Assumptions (v4a)'!F64 -> 77.093634
A11: Total Insurance Revenue | C11: =SUM(C6:C9) -> 352.66814 | D11: =SUM(D6:D9) -> 354.84819 | E11: =SUM(E6:E9) -> 357.09363
A13: INSURANCE SERVICE EXPENSE
A14: Actual claims incurred | C14: ='Assumptions (v4a)'!D18 -> 250 | D14: ='Assumptions (v4a)'!E18 -> 250 | E14: ='Assumptions (v4a)'!F18 -> 250
A15: Actual expenses incurred | C15: ='Assumptions (v4a)'!D19 -> 50 | D15: ='Assumptions (v4a)'!E19 -> 50 | E15: ='Assumptions (v4a)'!F19 -> 50
A17: Total Insurance Service Expense | C17: =-(C14+C15) -> -300 | D17: =-(D14+D15) -> -300 | E17: =-(E14+E15) -> -300
A19: INSURANCE SERVICE RESULT | C19: =C11+C17 -> 52.668144 | D19: =D11+D17 -> 54.848188 | E19: =E11+E17 -> 57.093634
A21: INSURANCE FINANCE INCOME / (EXPENSE)
A22: Accretion of BEL (discount unwind) | C22: =-'Assumptions (v4a)'!D44 -> -27.75091 | D22: =-'Assumptions (v4a)'!E44 -> -16.622325 | E22: =-'Assumptions (v4a)'!F44 -> -7.2815534
A23: Effect of discount rate changes | C23: =-'Assumptions (v4a)'!D45 -> 0 | D23: =-'Assumptions (v4a)'!E45 -> 0 | E23: =-'Assumptions (v4a)'!F45 -> 0
A24: Accretion of CSM | C24: =-'Assumptions (v4a)'!D62 -> -6.3496437 | D24: =-'Assumptions (v4a)'!E62 -> -4.3600886 | E24: =-'Assumptions (v4a)'!F62 -> -2.2454457
A25: Total Insurance Finance Income / (Expense) | C25: =SUM(C22:C24) -> -34.100554 | D25: =SUM(D22:D24) -> -20.982414 | E25: =SUM(E22:E24) -> -9.5269991
A27: NET INCOME | C27: =C19+C25 -> 18.56759 | D27: =D19+D25 -> 33.865775 | E27: =E19+E25 -> 47.566635
A29: Cumulative Profit | C29: =C27 -> 18.56759 | D29: =C29+D27 -> 52.433365 | E29: =D29+E27 -> 100
A31: KEY INSIGHTS:
A32: ⚠️ Actual claims (250) > Expected claims (200). The 50/yr difference hits profit immediately as experience variance.
A33: Revenue is based on EXPECTED costs (locked in), not actuals. So revenue stays the same even when claims blow out; the variance shows up in higher expense.
A34: This is why IFRS 17 shows BEL release (expected) as revenue and actuals as expense separately. When they differ, the P&L reveals whether the insurer is managing claims well.
A35: If profit were just "CSM + RA release", you'd never see that claims exceeded expectations. The loss would be hidden.
A37: WORKINGS (not part of the P&L)
A38: Cash outflows (for BS link)
A39: Total cash paid out (claims + expenses) | C39: ='Assumptions (v4a)'!D20 -> 300 | D39: ='Assumptions (v4a)'!E20 -> 300 | E39: ='Assumptions (v4a)'!F20 -> 300
A40: In this model, cash outflows = insurance service expense because claims are paid immediately when incurred.
A41: In practice these can differ due to settlement lags, expense accruals, or upfront acquisition costs.
A42: The BS cash line references cash outflows (not P&L expense) because it tracks actual cash movements.

Sheet Balance Sheet (v4a)
A1: BALANCE SHEET
A2: IFRS 17: Experience Variance (Option A)
B4: 45658 | C4: 46022 | D4: 46387 | E4: 46752
A5: ASSETS
A6: Cash & Investments | B6: ='Assumptions (v4a)'!C9 -> 1000 | C6: =B6-'P&L (v4a)'!C39 -> 700 | D6: =C6-'P&L (v4a)'!D39 -> 400 | E6: =D6-'P&L (v4a)'!E39 -> 100
A7: Total Assets | B7: =B6 -> 1000 | C7: =C6 -> 700 | D7: =D6 -> 400 | E7: =E6 -> 100
A9: LIABILITIES
A10: Insurance Contract Liability:
A11: BEL (Best Estimate Liability) | B11: ='Assumptions (v4a)'!G33 -> 698.34521 | C11: ='Assumptions (v4a)'!G34 -> 476.09612 | D11: ='Assumptions (v4a)'!G35 -> 242.71845 | E11: ='Assumptions (v4a)'!G36 -> 0
A12: Risk Adjustment | B12: ='Assumptions (v4a)'!C55 -> 90 | C12: =B12-'P&L (v4a)'!C8 -> 60 | D12: =C12-'P&L (v4a)'!D8 -> 30 | E12: =D12-'P&L (v4a)'!E8 -> 0
A13: Fulfilment Cash Flows (BEL + RA) | B13: =B11+B12 -> 788.34521 | C13: =C11+C12 -> 536.09612 | D13: =D11+D12 -> 272.71845 | E13: =E11+E12 -> 0
A14: Contractual Service Margin (CSM) | B14: ='Assumptions (v4a)'!C57 -> 211.65479 | C14: ='Assumptions (v4a)'!D65 -> 145.33629 | D14: ='Assumptions (v4a)'!E65 -> 74.848188 | E14: ='Assumptions (v4a)'!F65 -> 0
A15: Total Insurance Liability | B15: =B13+B14 -> 1000 | C15: =C13+C14 -> 681.43241 | D15: =D13+D14 -> 347.56664 | E15: =E13+E14 -> 0
A16: Total Liabilities | B16: =B15 -> 1000 | C16: =C15 -> 681.43241 | D16: =D15 -> 347.56664 | E16: =E15 -> 0
A18: EQUITY
A19: Retained Earnings | B19: 0 | C19: =B19+'P&L (v4a)'!C27 -> 18.56759 | D19: =C19+'P&L (v4a)'!D27 -> 52.433365 | E19: =D19+'P&L (v4a)'!E27 -> 100
A20: Total Equity | B20: =B19 -> 0 | C20: =C19 -> 18.56759 | D20: =D19 -> 52.433365 | E20: =E19 -> 100
A22: CHECK: Assets = Liabilities + Equity | B22: =IF(ABS(B7-B16-B20)<0.01,"✅ Balanced","❌ "&TEXT(B7-B16-B20,"#,##0.00")) -> ✅ Balanced | C22: =IF(ABS(C7-C16-C20)<0.01,"✅ Balanced","❌ "&TEXT(C7-C16-C20,"#,##0.00")) -> ✅ Balanced | D22: =IF(ABS(D7-D16-D20)<0.01,"✅ Balanced","❌ "&TEXT(D7-D16-D20,"#,##0.00")) -> ✅ Balanced | E22: =IF(ABS(E7-E16-E20)<0.01,"✅ Balanced","❌ "&TEXT(E7-E16-E20,"#,##0.00")) -> ✅ Balanced

Sheet Re-estimation (Option B) →

Sheet Assumptions (v4b)
A1: IFRS 17: Re-estimation (Option B)
A2: Simplifications:
A3: • Actual claims exceed expected; insurer re-estimates future claims at end of Year 1
A4: • CSM absorbs the BEL increase from re-estimation (no onerous contract)
A5: • Assets consist solely of cash; all finance through P&L (no OCI)
A7: CONTRACT DETAILS
A8: Coverage period (years) | C8: 3
A9: Premiums collected (upfront) | C9: 1000
A11: ORIGINAL EXPECTED CASH FLOWS (at inception) | C11: Total | D11: 46022 | E11: 46387 | F11: 46752
A12: Expected claims | C12: 600 | D12: =C12/C8 -> 200 | E12: =C12/C8 -> 200 | F12: =C12/C8 -> 200
A13: Expected expenses | C13: 150 | D13: =C13/C8 -> 50 | E13: =C13/C8 -> 50 | F13: =C13/C8 -> 50
A14: Total expected undiscounted outflows | C14: =C12+C13 -> 750 | D14: =D12+D13 -> 250 | E14: =E12+E13 -> 250 | F14: =F12+F13 -> 250
A15: Risk Adjustment (total, undiscounted) | C15: 90
A17: REVISED EXPECTED CASH FLOWS (at end of Year 1) | E17: 46387 | F17: 46752
A18: Revised expected claims | E18: 250 | F18: 250
A19: Expected expenses (unchanged) | E19: =E13 -> 50 | F19: =F13 -> 50
A20: Total revised outflows | E20: =E18+E19 -> 300 | F20: =F18+F19 -> 300
A22: ACTUAL CASH FLOWS | D22: 46022 | E22: 46387 | F22: 46752
A23: Actual claims | D23: 250 | E23: 250 | F23: 250
A24: Actual expenses | D24: =D13 -> 50 | E24: =E13 -> 50 | F24: =F13 -> 50
A25: Total actual outflows | D25: =D23+D24 -> 300 | E25: =E23+E24 -> 300 | F25: =F23+F24 -> 300
A27: YIELD CURVE (Spot Rates) | D27: 1Y Spot | E27: 2Y Spot | F27: 3Y Spot
A28: Curve at Inception (t=0) | D28: 0.03 | E28: 0.035 | F28: 0.04
A29: Curve at End Year 1 (t=1) | D29: 0.03 | E29: 0.035
A30: Curve at End Year 2 (t=2) | D30: 0.03
A32: DISCOUNT FACTORS | D32: DF 1Y | E32: DF 2Y | F32: DF 3Y
A33: DFs at Inception (t=0) | D33: =1/(1+D28)^1 -> 0.97087379 | E33: =1/(1+E28)^2 -> 0.9335107 | F33: =1/(1+F28)^3 -> 0.88899636
A34: DFs at End Year 1 (t=1) | D34: =1/(1+D29)^1 -> 0.97087379 | E34: =1/(1+E29)^2 -> 0.9335107
A35: DFs at End Year 2 (t=2) | D35: =1/(1+D30)^1 -> 0.97087379
A37: BEL (DISCOUNTED) AT EACH DATE | D37: PV of Y1 CFs | E37: PV of Y2 CFs | F37: PV of Y3 CFs | G37: BEL Total
A38: BEL at Inception (t=0), original estimates | D38: =D14*D33 -> 242.71845 | E38: =E14*E33 -> 233.37768 | F38: =F14*F33 -> 222.24909 | G38: =SUM(D38:F38) -> 698.34521
A39: BEL at End Y1 (t=1), original estimates, NEW curve | E39: =E14*D34 -> 242.71845 | F39: =F14*E34 -> 233.37768 | G39: =SUM(E39:F39) -> 476.09612
A40: BEL at End Y1 (t=1), REVISED estimates, NEW curve | E40: =E20*D34 -> 291.26214 | F40: =F20*E34 -> 280.05321 | G40: =SUM(E40:F40) -> 571.31535
A41: BEL at End Y2 (t=2), REVISED estimates, NEW curve | F41: =F20*D35 -> 291.26214 | G41: =F41 -> 291.26214
A42: BEL at End Y3 (t=3) | G42: 0
A44: BEL at End Y1, using OLD curve (for accretion) | E44: =E14*D33 -> 242.71845 | F44: =F14*E33 -> 233.37768 | G44: =SUM(E44:F44) -> 476.09612
A45: BEL at End Y2, using OLD curve (for accretion) | F45: =F20*D33 -> 291.26214 | G45: =F45 -> 291.26214
A47: BEL ROLLFORWARD COMPONENTS | D47: 46022 | E47: 46387 | F47: 46752
A48: Opening BEL | D48: =G38 -> 698.34521 | E48: =G40 -> 571.31535 | F48: =G41 -> 291.26214
A49: Less: BEL release (expected outflows) | D49: =-D14 -> -250 | E49: =-E20 -> -300 | F49: =-F20 -> -300
...

Sheet P&L (v4b)
A1: INCOME STATEMENT (P&L)
A2: IFRS 17: Re-estimation (Option B)
C4: 46022 | D4: 46387 | E4: 46752
A5: INSURANCE REVENUE
A6: BEL release: expected claims | C6: ='Assumptions (v4b)'!D12 -> 200 | D6: ='Assumptions (v4b)'!E18 -> 250 | E6: ='Assumptions (v4b)'!F18 -> 250
A7: BEL release: expected expenses | C7: ='Assumptions (v4b)'!D13 -> 50 | D7: ='Assumptions (v4b)'!E19 -> 50 | E7: ='Assumptions (v4b)'!F19 -> 50
A8: Risk Adjustment release | C8: ='Assumptions (v4b)'!C58 -> 30 | D8: ='Assumptions (v4b)'!C58 -> 30 | E8: ='Assumptions (v4b)'!C58 -> 30
A9: CSM release (earned profit) | C9: =-'Assumptions (v4b)'!D71 -> 40.928403 | D9: =-'Assumptions (v4b)'!E71 -> 42.156255 | E9: =-'Assumptions (v4b)'!F71 -> 43.420942
A11: Total Insurance Revenue | C11: =SUM(C6:C9) -> 320.9284 | D11: =SUM(D6:D9) -> 372.15625 | E11: =SUM(E6:E9) -> 373.42094
A13: INSURANCE SERVICE EXPENSE
A14: Actual claims incurred | C14: ='Assumptions (v4b)'!D23 -> 250 | D14: ='Assumptions (v4b)'!E23 -> 250 | E14: ='Assumptions (v4b)'!F23 -> 250
A15: Actual expenses incurred | C15: ='Assumptions (v4b)'!D24 -> 50 | D15: ='Assumptions (v4b)'!E24 -> 50 | E15: ='Assumptions (v4b)'!F24 -> 50
A17: Total Insurance Service Expense | C17: =-(C14+C15) -> -300 | D17: =-(D14+D15) -> -300 | E17: =-(E14+E15) -> -300
A19: INSURANCE SERVICE RESULT | C19: =C11+C17 -> 20.928403 | D19: =D11+D17 -> 72.156255 | E19: =E11+E17 -> 73.420942
A21: INSURANCE FINANCE INCOME / (EXPENSE)
A22: Accretion of BEL (discount unwind) | C22: =-'Assumptions (v4b)'!D50 -> -27.75091 | D22: =-'Assumptions (v4b)'!E50 -> -19.94679 | E22: =-'Assumptions (v4b)'!F50 -> -8.7378641
A23: Effect of discount rate changes | C23: =-'Assumptions (v4b)'!D51 -> 0 | D23: =-'Assumptions (v4b)'!E51 -> 0 | E23: =-'Assumptions (v4b)'!F51 -> 0
A24: Accretion of CSM | C24: =-'Assumptions (v4b)'!D69 -> -6.3496437 | D24: =-'Assumptions (v4b)'!E69 -> -2.4557042 | E24: =-'Assumptions (v4b)'!F69 -> -1.2646876
A25: Total Insurance Finance Income / (Expense) | C25: =SUM(C22:C24) -> -34.100554 | D25: =SUM(D22:D24) -> -22.402494 | E25: =SUM(E22:E24) -> -10.002552
A27: NET INCOME | C27: =C19+C25 -> -13.172151 | D27: =D19+D25 -> 49.753761 | E27: =E19+E25 -> 63.418391
A29: Cumulative Profit | C29: =C27 -> -13.172151 | D29: =C29+D27 -> 36.581609 | E29: =D29+E27 -> 100
A31: KEY INSIGHTS:
A32: ⚠️ Option B re-estimates future claims upward and adjusts the CSM, so expected claims in Yr 2-3 = 250 (matching actuals). Revenue rises in later years.
A33: In Year 1 the BEL release is still based on the ORIGINAL expected claims (200), so the 50 experience variance hits Year 1 profit, just like Option A.
A34: This is why IFRS 17 shows BEL release (expected) as revenue and actuals as expense separately. When they differ, the P&L reveals whether the insurer is managing claims well.
A35: If profit were just "CSM + RA release", you'd never see that claims exceeded expectations. The loss would be hidden.
A37: WORKINGS (not part of the P&L)
A38: Cash outflows (for BS link)
A39: Total cash paid out (claims + expenses) | C39: ='Assumptions (v4b)'!D25 -> 300 | D39: ='Assumptions (v4b)'!E25 -> 300 | E39: ='Assumptions (v4b)'!F25 -> 300
A40: In this model, cash outflows = insurance service expense because claims are paid immediately when incurred.
A41: In practice these can differ due to settlement lags, expense accruals, or upfront acquisition costs.
A42: The BS cash line references cash outflows (not P&L expense) because it tracks actual cash movements.

Sheet Balance Sheet (v4b)
A1: BALANCE SHEET
A2: IFRS 17: Re-estimation (Option B)
B4: 45658 | C4: 46022 | D4: 46387 | E4: 46752
A5: ASSETS
A6: Cash & Investments | B6: ='Assumptions (v4b)'!C9 -> 1000 | C6: =B6-'P&L (v4b)'!C39 -> 700 | D6: =C6-'P&L (v4b)'!D39 -> 400 | E6: =D6-'P&L (v4b)'!E39 -> 100
A7: Total Assets | B7: =B6 -> 1000 | C7: =C6 -> 700 | D7: =D6 -> 400 | E7: =E6 -> 100
A9: LIABILITIES
A10: Insurance Contract Liability:
A11: BEL (Best Estimate Liability) | B11: ='Assumptions (v4b)'!G38 -> 698.34521 | C11: ='Assumptions (v4b)'!G40 -> 571.31535 | D11: ='Assumptions (v4b)'!G41 -> 291.26214 | E11: ='Assumptions (v4b)'!G42 -> 0
A12: Risk Adjustment | B12: ='Assumptions (v4b)'!C62 -> 90 | C12: =B12-'P&L (v4b)'!C8 -> 60 | D12: =C12-'P&L (v4b)'!D8 -> 30 | E12: =D12-'P&L (v4b)'!E8 -> 0
A13: Fulfilment Cash Flows (BEL + RA) | B13: =B11+B12 -> 788.34521 | C13: =C11+C12 -> 631.31535 | D13: =D11+D12 -> 321.26214 | E13: =E11+E12 -> 0
A14: Contractual Service Margin (CSM) | B14: ='Assumptions (v4b)'!C64 -> 211.65479 | C14: ='Assumptions (v4b)'!D73 -> 81.856805 | D14: ='Assumptions (v4b)'!E73 -> 42.156255 | E14: ='Assumptions (v4b)'!F73 -> 0
A15: Total Insurance Liability | B15: =B13+B14 -> 1000 | C15: =C13+C14 -> 713.17215 | D15: =D13+D14 -> 363.41839 | E15: =E13+E14 -> 0
A16: Total Liabilities | B16: =B15 -> 1000 | C16: =C15 -> 713.17215 | D16: =D15 -> 363.41839 | E16: =E15 -> 0
A18: EQUITY
A19: Retained Earnings | B19: 0 | C19: =B19+'P&L (v4b)'!C27 -> -13.172151 | D19: =C19+'P&L (v4b)'!D27 -> 36.581609 | E19: =D19+'P&L (v4b)'!E27 -> 100
A20: Total Equity | B20: =B19 -> 0 | C20: =C19 -> -13.172151 | D20: =D19 -> 36.581609 | E20: =E19 -> 100
A22: CHECK: Assets = Liabilities + Equity | B22: =IF(ABS(B7-B16-B20)<0.01,"✅ Balanced","❌ "&TEXT(B7-B16-B20,"#,##0.00")) -> ✅ Balanced | C22: =IF(ABS(C7-C16-C20)<0.01,"✅ Balanced","❌ "&TEXT(C7-C16-C20,"#,##0.00")) -> ✅ Balanced | D22: =IF(ABS(D7-D16-D20)<0.01,"✅ Balanced","❌ "&TEXT(D7-D16-D20,"#,##0.00")) -> ✅ Balanced | E22: =IF(ABS(E7-E16-E20)<0.01,"✅ Balanced","❌ "&TEXT(E7-E16-E20,"#,##0.00")) -> ✅ Balanced

Sheet Claim Development →

Sheet Assumptions (Claim Dev)
A1: IFRS 17: Simple Model v1.5 — Claim Development
A2: Simplifications:
A3: • Actual claims and expenses = expected each year (no experience variance)
A4: • No discounting (0% discount rate), all cash flows at nominal value
A5: • Assets consist solely of cash (no investment portfolio or investment income)
A6: • Claims are INCURRED evenly but PAID over 2 years (see claim development below)
A7: • Risk Adjustment released linearly over the coverage period
A9: Contract Details
A10: Coverage period (years) | B10: 3
A11: Discount rate | B11: 0
A13: Cash Flows at Inception | B13: Total | C13: Per Year
A14: Premiums collected (upfront) | B14: 1000
A15: Expected claims | B15: 600 | C15: =B15/B10 -> 200
A16: Expected expenses | B16: 150 | C16: =B16/B10 -> 50
A17: Risk Adjustment (total) | B17: 90 | C17: =B17/B10 -> 30
A19: Building Blocks at Inception
A20: BEL (Best Estimate Liability) | B20: =B15+B16 -> 750
A21: Risk Adjustment | B21: =B17 -> 90
A22: Contractual Service Margin (CSM) | B22: =B14-B20-B17 -> 160
A23: Total Insurance Liability at Inception | B23: =B20+B21+B22 -> 1000
A25: Release Pattern
A26: CSM release per year | B26: =B22/B10 -> 53.333333
A27: RA release per year | B27: =B17/B10 -> 30
A29: How it works:
A30: 1. The premium creates a balanced entry: cash +1,000 on the asset side and insurance liability +1,000 on the liability side
A31: The CSM acts as the plug that forces Day 1 profit to zero (Liability = BEL + RA + CSM = Premium)
A32: 2. Revenue then emerges over the coverage period as the liability components (BEL, RA, CSM) are released to the P&L
A33: 3. The CSM is the 'unearned profit'; it smooths profit recognition over the coverage period
A35: Claim Development Pattern
A36: % paid in year incurred | B36: 0.8
A37: % paid following year | B37: =1-B36 -> 0.2
A39: Claims paid schedule (per cohort of incurred claims)
A40: Paid in year of incurral | B40: =C15*B36 -> 160
A41: Paid one year later | B41: =C15*B37 -> 40
A43: How claim development works:
A44: 1. Claims are INCURRED evenly each year (200/yr) and recognized in the P&L when incurred
A45: 2. But cash PAYMENT lags: 80% paid in the year incurred, 20% paid the following year
A46: 3. The unpaid portion sits on the BS as a 'Claims Payable' liability (separate from the insurance contract liability)
A47: 4. P&L is unchanged vs v1 (incurred basis); only cash and the BS change
A48: 5. A Year 4 column is needed to capture the final tail payment from Year 3's incurred claims

Sheet P&L (Claim Dev)
A1: INCOME STATEMENT (P&L) — v1.5
A2: Insurance Company: IFRS 17 Example
C4: 46022 | D4: 46387 | E4: 46752 | F4: 47117
A5: INSURANCE REVENUE
A6: BEL release: expected claims | C6: ='Assumptions (Claim Dev)'!C15 -> 200 | D6: ='Assumptions (Claim Dev)'!C15 -> 200 | E6: ='Assumptions (Claim Dev)'!C15 -> 200 | F6: 0
A7: BEL release: expected expenses | C7: ='Assumptions (Claim Dev)'!C16 -> 50 | D7: ='Assumptions (Claim Dev)'!C16 -> 50 | E7: ='Assumptions (Claim Dev)'!C16 -> 50 | F7: 0
A8: Risk Adjustment release | C8: ='Assumptions (Claim Dev)'!B27 -> 30 | D8: ='Assumptions (Claim Dev)'!B27 -> 30 | E8: ='Assumptions (Claim Dev)'!B27 -> 30 | F8: 0
A9: CSM release (earned profit) | C9: ='Assumptions (Claim Dev)'!B26 -> 53.333333 | D9: ='Assumptions (Claim Dev)'!B26 -> 53.333333 | E9: ='Assumptions (Claim Dev)'!B26 -> 53.333333 | F9: 0
A11: Total Insurance Revenue | C11: =SUM(C6:C9) -> 333.33333 | D11: =SUM(D6:D9) -> 333.33333 | E11: =SUM(E6:E9) -> 333.33333 | F11: =SUM(F6:F9) -> 0
A13: INSURANCE SERVICE EXPENSE
A14: Actual claims incurred | C14: ='Assumptions (Claim Dev)'!C15 -> 200 | D14: ='Assumptions (Claim Dev)'!C15 -> 200 | E14: ='Assumptions (Claim Dev)'!C15 -> 200 | F14: 0
A15: Actual expenses incurred | C15: ='Assumptions (Claim Dev)'!C16 -> 50 | D15: ='Assumptions (Claim Dev)'!C16 -> 50 | E15: ='Assumptions (Claim Dev)'!C16 -> 50 | F15: 0
A17: Total Insurance Service Expense | C17: =-(C14+C15) -> -250 | D17: =-(D14+D15) -> -250 | E17: =-(E14+E15) -> -250 | F17: =-(F14+F15) -> 0
A20: INSURANCE SERVICE RESULT | C20: =C11+C17 -> 83.333333 | D20: =D11+D17 -> 83.333333 | E20: =E11+E17 -> 83.333333 | F20: =F11+F17 -> 0
A22: Net Income | C22: =C20 -> 83.333333 | D22: =D20 -> 83.333333 | E22: =E20 -> 83.333333 | F22: =F20 -> 0
A24: Cumulative Profit | C24: =C22 -> 83.333333 | D24: =C24+D22 -> 166.66667 | E24: =D24+E22 -> 250 | F24: =E24+F22 -> 250
A26: KEY INSIGHTS:
A27: ⚠️ Actual claims INCURRED = Expected (no experience variance). But cash PAID lags incurral.
A28: P&L is identical to v1 — claims hit the P&L when incurred, not when paid
A29: The difference vs v1 shows up on the Balance Sheet: a new 'Claims Payable' line + delayed cash outflow
A30: Year 4 has no P&L activity (coverage ended); only the tail payment of the unpaid Y3 claims
A32: WORKINGS (not part of the P&L)
A33: Cash outflows (for BS link) — claims paid on development pattern | C33: Year 1 | D33: Year 2 | E33: Year 3 | F33: Year 4
A34: Claims paid — current year (% of this year's incurred) | C34: =C14*'Assumptions (Claim Dev)'!$B$36 -> 160 | D34: =D14*'Assumptions (Claim Dev)'!$B$36 -> 160 | E34: =E14*'Assumptions (Claim Dev)'!$B$36 -> 160 | F34: =F14*'Assumptions (Claim Dev)'!$B$36 -> 0
A35: Claims paid — tail from prior year (% of prior year's incurred) | C35: 0 | D35: =C14*'Assumptions (Claim Dev)'!$B$37 -> 40 | E35: =D14*'Assumptions (Claim Dev)'!$B$37 -> 40 | F35: =E14*'Assumptions (Claim Dev)'!$B$37 -> 40
A36: Expenses paid (immediate) | C36: =C15 -> 50 | D36: =D15 -> 50 | E36: =E15 -> 50 | F36: =F15 -> 0
A37: Total cash paid out | C37: =C34+C35+C36 -> 210 | D37: =D34+D35+D36 -> 250 | E37: =E34+E35+E36 -> 250 | F37: =F34+F35+F36 -> 40
A39: Claims payable (unpaid incurred claims carried to next year)
A40: = Current year incurred × % paid following year | C40: =C14*'Assumptions (Claim Dev)'!$B$37 -> 40 | D40: =D14*'Assumptions (Claim Dev)'!$B$37 -> 40 | E40: =E14*'Assumptions (Claim Dev)'!$B$37 -> 40 | F40: =F14*'Assumptions (Claim Dev)'!$B$37 -> 0

Sheet Balance Sheet (Claim Dev)
A1: BALANCE SHEET — v1.5
A2: Insurance Company: IFRS 17 Example
B4: 45658 | C4: 46022 | D4: 46387 | E4: 46752 | F4: 47117
A5: ASSETS
A6: Cash & Investments ← 1,000 premium received upfront | B6: ='Assumptions (Claim Dev)'!B14 -> 1000 | C6: =B6-'P&L (Claim Dev)'!C37 -> 790 | D6: =C6-'P&L (Claim Dev)'!D37 -> 540 | E6: =D6-'P&L (Claim Dev)'!E37 -> 290 | F6: =E6-'P&L (Claim Dev)'!F37 -> 250
A7: Total Assets | B7: =B6 -> 1000 | C7: =C6 -> 790 | D7: =D6 -> 540 | E7: =E6 -> 290 | F7: =F6 -> 250
A9: LIABILITIES
A10: Liability for Remaining Coverage (LRC):
A11: BEL (Best Estimate Liability) | B11: ='Assumptions (Claim Dev)'!B20 -> 750 | C11: =B11-'P&L (Claim Dev)'!C6-'P&L (Claim Dev)'!C7 -> 500 | D11: =C11-'P&L (Claim Dev)'!D6-'P&L (Claim Dev)'!D7 -> 250 | E11: =D11-'P&L (Claim Dev)'!E6-'P&L (Claim Dev)'!E7 -> 0 | F11: =E11-'P&L (Claim Dev)'!F6-'P&L (Claim Dev)'!F7 -> 0
A12: Risk Adjustment | B12: ='Assumptions (Claim Dev)'!B21 -> 90 | C12: =B12-'P&L (Claim Dev)'!C8 -> 60 | D12: =C12-'P&L (Claim Dev)'!D8 -> 30 | E12: =D12-'P&L (Claim Dev)'!E8 -> 0 | F12: =E12-'P&L (Claim Dev)'!F8 -> 0
A13: Fulfilment Cash Flows (BEL + RA) | B13: =B11+B12 -> 840 | C13: =C11+C12 -> 560 | D13: =D11+D12 -> 280 | E13: =E11+E12 -> 0 | F13: =F11+F12 -> 0
A14: Contractual Service Margin (CSM) | B14: ='Assumptions (Claim Dev)'!B22 -> 160 | C14: =B14-'P&L (Claim Dev)'!C9 -> 106.66667 | D14: =C14-'P&L (Claim Dev)'!D9 -> 53.333333 | E14: =D14-'P&L (Claim Dev)'!E9 -> 0 | F14: =E14-'P&L (Claim Dev)'!F9 -> 0
A15: Subtotal LRC | B15: =B11+B12+B14 -> 1000 | C15: =C11+C12+C14 -> 666.66667 | D15: =D11+D12+D14 -> 333.33333 | E15: =E11+E12+E14 -> 0 | F15: =F11+F12+F14 -> 0
A17: Liability for Incurred Claims (LIC):
A18: Claims Payable (unpaid incurred claims) | B18: 0 | C18: =B18+'P&L (Claim Dev)'!C14-'P&L (Claim Dev)'!C34-'P&L (Claim Dev)'!C35 -> 40 | D18: =C18+'P&L (Claim Dev)'!D14-'P&L (Claim Dev)'!D34-'P&L (Claim Dev)'!D35 -> 40 | E18: =D18+'P&L (Claim Dev)'!E14-'P&L (Claim Dev)'!E34-'P&L (Claim Dev)'!E35 -> 40 | F18: =E18+'P&L (Claim Dev)'!F14-'P&L (Claim Dev)'!F34-'P&L (Claim Dev)'!F35 -> 0
A19: Total Insurance Contract Liability | B19: =B15+B18 -> 1000 | C19: =C15+C18 -> 706.66667 | D19: =D15+D18 -> 373.33333 | E19: =E15+E18 -> 40 | F19: =F15+F18 -> 0
A21: EQUITY
A22: Retained Earnings | B22: 0 | C22: =B22+'P&L (Claim Dev)'!C22 -> 83.333333 | D22: =C22+'P&L (Claim Dev)'!D22 -> 166.66667 | E22: =D22+'P&L (Claim Dev)'!E22 -> 250 | F22: =E22+'P&L (Claim Dev)'!F22 -> 250
A23: Total Equity | B23: =B22 -> 0 | C23: =C22 -> 83.333333 | D23: =D22 -> 166.66667 | E23: =E22 -> 250 | F23: =F22 -> 250
A25: CHECK: Assets = Liabilities + Equity | B25: =IF(ABS(B7-B19-B23)<0.01,"✅ Balanced","❌ Error") -> ✅ Balanced | C25: =IF(ABS(C7-C19-C23)<0.01,"✅ Balanced","❌ Error") -> ✅ Balanced | D25: =IF(ABS(D7-D19-D23)<0.01,"✅ Balanced","❌ Error") -> ✅ Balanced | E25: =IF(ABS(E7-E19-E23)<0.01,"✅ Balanced","❌ Error") -> ✅ Balanced | F25: =IF(ABS(F7-F19-F23)<0.01,"✅ Balanced","❌ Error") -> ✅ Balanced
